Workbook

Sheet 대시보드
B1: 🏠 우리집 주식회사 · 자산관리 대시보드
B2: ="기준월 "&설정!$B$3&" 결산 · 보기: "&설정!$B$4&" · 금액 단위: 원" -> 기준월 2026-09 결산 · 보기: 전체 · 금액 단위: 원
B4: 기준월 (yyyy-mm) | C4: 2026-09 | D4: 보기 | E4: 전체 | G4: 오늘 | H4: =설정!$B$10 -> 46306 | I4: ← 노란 칸을 바꾸면 모든 시트가 다시 계산됩니다
B6: 순자산 | D6: 저축률 (이번 달) | F6: 월 투자 납입액 | H6: 투자+연금 자산 | J6: 소비 예산 집행률
B7: =재무상태표!B11 -> 0 | D7: =IF(설정!$B$4="공동","",손익!M37) -> 0 | F7: =손익!M45 -> 0 | H7: =재무상태표!B13 -> 0 | J7: =예산!G45 -> 0
B8: ="약 "&TEXT(재무상태표!B11/100000000,"0.00")&"억원" -> 약 0.00억원 | D8: =IF(설정!$B$4="공동","공동 보기는 직접 소득이 없어 계산하지 않음","목표 "&TEXT(설정!$B$12,"0%")&" · 12개월 "&TEXT(손익!N37,"0.0%")) -> 목표 30% · 12개월 0.0% | F8: ="목표 "&TEXT(설정!$B$29,"#,##0")&" · 납입률 "&TEXT(손익!M51,"0%") -> 목표 2,200,000 · 납입률 0% | H8: ="총자산의 "&TEXT(IF(재무상태표!B9=0,0,재무상태표!B13/재무상태표!B9),"0.0%") -> 총자산의 0.0% | J8: =IF(설정!$B$4="전체","실적 "&TEXT(예산!F45,"#,##0")&" / 예산 "&TEXT(예산!E45,"#,##0"),"가계 예산 중 "&설정!$B$4&" 사용분 "&TEXT(예산!F45,"#,##0")) -> 실적 0 / 예산 5,680,000
B9: =IF(재무상태표!D11>=0,"✅ 전월 대비 증가 ","⚠ 전월 대비 감소 ")&TEXT(재무상태표!D11,"+#,##0;-#,##0") -> ✅ 전월 대비 증가 +0 | D9: =IF(설정!$B$4="공동","- 해당 없음",IF(손익!M9=0,"- 소득 데이터 없음",IF(손익!M37>=설정!$B$12,"✅ 달성","⚠ 미달"))) -> - 소득 데이터 없음 | F9: =IF(손익!M45>=설정!$B$29,"✅ 달성","⚠ 미달 "&TEXT(설정!$B$29-손익!M45,"#,##0")) -> ⚠ 미달 2,200,000 | H9: =IF(재무상태표!D13>=0,"✅ 증가 ","⚠ 감소 ")&TEXT(재무상태표!D13,"+#,##0;-#,##0") -> ✅ 증가 +0 | J9: =IF(COUNTIF(예산!I4:I43,"*초과*")>0,"🔴 초과 카테고리 "&COUNTIF(예산!I4:I43,"*초과*")&"개",IF(예산!G45>=0.9,"⚠ 주의","✅ 양호")) -> ✅ 양호
B11: 비상자금 | D11: 부채비율 | F11: DSR | H11: 목표 달성률 (가중) | J11: 재무자립도
B12: =IF(손익!P49=0,0,재무상태표!B15/손익!P49) -> 0 | D12: =재무상태표!B14 -> 0 | F12: =부채!B20 -> 0 | H12: =목표!B16 -> 0 | J12: =IF(손익!O35=0,0,손익!O7/손익!O35) -> 0
B13: ="목표 "&설정!$B$13&"개월 · "&TEXT(재무상태표!B15,"#,##0")&"원" -> 목표 6개월 · 0원 | D13: ="상한 "&TEXT(설정!$B$14,"0%")&" · 부채 "&TEXT(재무상태표!B10/100000000,"0.00")&"억" -> 상한 40% · 부채 0.00억 | F13: ="상한 "&TEXT(설정!$B$15,"0%")&" · 월 원리금 "&TEXT(부채!B17,"#,##0") -> 상한 30% · 월 원리금 0 | H13: ="노후 준비율 "&TEXT(목표!B17,"0%") -> 노후 준비율 0% | J13: ="월 수동소득 "&TEXT(손익!O7,"#,##0")&"원" -> 월 수동소득 0원
B14: =IF(IF(손익!P49=0,0,재무상태표!B15/손익!P49)>=설정!$B$13,"✅ 달성","⚠ 미달") -> ⚠ 미달 | D14: =IF(재무상태표!B14<=설정!$B$14,"✅ 양호","⚠ 주의") -> ✅ 양호 | F14: =IF(부채!B20<=설정!$B$15,"✅ 양호","⚠ 주의") -> ✅ 양호 | H14: =IF(목표!B18=0,"✅ 모두 순항","⚠ 지연 "&목표!B18&"건") -> ✅ 모두 순항 | J14: ="장기 목표 100% (수동소득 ≥ 생활비)" -> 장기 목표 100% (수동소득 ≥ 생활비)
B16: 🔔 이번 달 알림 (내부통제) | H16: 👨‍👩‍👧 구성원별 순자산 (기준월)
B17: =IFERROR(INDEX($N$17:$N$27,MATCH(1,$O$17:$O$27,0)),"") -> ⚠ 투자 납입 2,200,000원 부족 (목표 2,200,000) | H17: 구성원 | I17: 자산 | J17: 부채 | K17: 순자산 | N17: =IF(COUNTIF(예산!I4:I43,"*초과*")>0,"🔴 예산 초과: "&_xlfn.TEXTJOIN(", ",TRUE(),예산!M4:M43),"") | O17: =IF(N17="",0,1)+N(O16) -> 0
B18: =IFERROR(INDEX($N$17:$N$27,MATCH(2,$O$17:$O$27,0)),"") | H18: =재무상태표!A24 -> 본인 | I18: =재무상태표!B24 -> 0 | J18: =재무상태표!C24 -> 0 | K18: =재무상태표!D24 -> 0 | N18: =IF(AND(NOT(설정!$B$4="공동"),손익!M9>0,손익!M37<설정!$B$12),"⚠ 저축률 "&TEXT(손익!M37,"0.0%")&" — 목표 "&TEXT(설정!$B$12,"0%")&" 미달","") | O18: =IF(N18="",0,1)+N(O17) -> 0
B19: =IFERROR(INDEX($N$17:$N$27,MATCH(3,$O$17:$O$27,0)),"") | H19: =재무상태표!A25 -> 배우자 | I19: =재무상태표!B25 -> 0 | J19: =재무상태표!C25 -> 0 | K19: =재무상태표!D25 -> 0 | N19: =IF(손익!M45<설정!$B$29,"⚠ 투자 납입 "&TEXT(설정!$B$29-손익!M45,"#,##0")&"원 부족 (목표 "&TEXT(설정!$B$29,"#,##0")&")","") -> ⚠ 투자 납입 2,200,000원 부족 (목표 2,200,000) | O19: =IF(N19="",0,1)+N(O18) -> 1
B20: =IFERROR(INDEX($N$17:$N$27,MATCH(4,$O$17:$O$27,0)),"") | H20: =재무상태표!A26 -> 공동 | I20: =재무상태표!B26 -> 0 | J20: =재무상태표!C26 -> 0 | K20: =재무상태표!D26 -> 0 | N20: =IF(AND(손익!P49>0,IF(손익!P49=0,0,재무상태표!B15/손익!P49)<설정!$B$13),"⚠ 비상자금 "&TEXT(IF(손익!P49=0,0,재무상태표!B15/손익!P49),"0.0")&"개월 — 목표까지 "&TEXT((설정!$B$13-IF(손익!P49=0,0,재무상태표!B15/손익!P49))*손익!P49,"#,##0")&"원 더 필요","") | O20: =IF(N20="",0,1)+N(O19) -> 1
B21: =IFERROR(INDEX($N$17:$N$27,MATCH(5,$O$17:$O$27,0)),"") | H21: =재무상태표!A27 -> 합계 | I21: =재무상태표!B27 -> 0 | J21: =재무상태표!C27 -> 0 | K21: =재무상태표!D27 -> 0 | N21: =IF(AND(설정!$B$4="전체",COUNTIF(투자!F4:F8,"*리밸런싱*")>0),"⚖ 리밸런싱 검토: "&_xlfn.TEXTJOIN(", ",TRUE(),투자!H4:H8),"") | O21: =IF(N21="",0,1)+N(O20) -> 1
B22: =IFERROR(INDEX($N$17:$N$27,MATCH(6,$O$17:$O$27,0)),"") | N22: =IF(OR(재무상태표!B14>설정!$B$14,부채!B20>설정!$B$15),"⚠ 부채 관리: 부채비율 "&TEXT(재무상태표!B14,"0%")&" · DSR "&TEXT(부채!B20,"0%"),"") | O22: =IF(N22="",0,1)+N(O21) -> 1
B23: =IFERROR(INDEX($N$17:$N$27,MATCH(7,$O$17:$O$27,0)),"") | H23: 🎯 목표 진척 | N23: =IF(COUNTIF(일정!H4:H63,"?*")>0,"🗓 다가오는 일정: "&_xlfn.TEXTJOIN(", ",TRUE(),일정!H4:H63),"") | O23: =IF(N23="",0,1)+N(O22) -> 1
B24: =IFERROR(INDEX($N$17:$N$27,MATCH(8,$O$17:$O$27,0)),"") | H24: 목표 | I24: 진척률 | J24: 상태 | K24: 필요 월적립 | N24: =IF(목표!B18>0,"🎯 목표 지연: "&_xlfn.TEXTJOIN(", ",TRUE(),목표!P4:P13),"") | O24: =IF(N24="",0,1)+N(O23) -> 1
B25: =IFERROR(INDEX($N$17:$N$27,MATCH(9,$O$17:$O$27,0)),"") | H25: =IF(목표!A4="","",목표!A4) -> 비상자금 | I25: =IF(H25="","",목표!J4) | J25: =IF(H25="","",목표!L4) | K25: =IF(H25="","",목표!N4) -> 0 | N25: =IF(AND(현금흐름!$B$5>0,COUNTIF(현금흐름!I11:I16,"*부족*")>0),"🔴 잔고 부족 예상: "&_xlfn.TEXTJOIN(", ",TRUE(),현금흐름!J11:J16),"") | O25: =IF(N25="",0,1)+N(O24) -> 1
B26: =IFERROR(INDEX($N$17:$N$27,MATCH(10,$O$17:$O$27,0)),"") | H26: =IF(목표!A5="","",목표!A5) | I26: =IF(H26="","",목표!J5) | J26: =IF(H26="","",목표!L5) | K26: =IF(H26="","",목표!N5) | N26: =IF(AND(COUNTA(보험!A4:A13)>0,보험!B24>0),"🛡 보장 공백 "&보험!B24&"건 — 보험 탭 확인","") | O26: =IF(N26="",0,1)+N(O25) -> 1
B27: =IFERROR(INDEX($N$17:$N$27,MATCH(11,$O$17:$O$27,0)),"") | H27: =IF(목표!A6="","",목표!A6) | I27: =IF(H27="","",목표!J6) | J27: =IF(H27="","",목표!L6) | K27: =IF(H27="","",목표!N6) | N27: =IF(손익!M52>0,"❓ 미분류 거래 "&TEXT(손익!M52,"#,##0")&"원 — 카테고리 지정 필요","") | O27: =IF(N27="",0,1)+N(O26) -> 1
B28: =IF(MAX(O17:O27)=0,"✅ 이상 없음 — 이번 달도 잘 운영되었습니다","") | H28: =IF(목표!A7="","",목표!A7) | I28: =IF(H28="","",목표!J7) | J28: =IF(H28="","",목표!L7) | K28: =IF(H28="","",목표!N7)
H29: =IF(목표!A8="","",목표!A8) | I29: =IF(H29="","",목표!J8) | J29: =IF(H29="","",목표!L8) | K29: =IF(H29="","",목표!N8)

Sheet 사용법
B1: 우리집 주식회사 자산관리 대시보드 - 사용법
B2: 가정을 기업처럼: 재무상태표(얼마 가졌나) · 손익계산서(얼마 남나) · 현금흐름(모자라지 않나) · 예산(계획대로 쓰나) · 목표(어디까지 왔나) · 리스크(버틸 수 있나)
B4: ■ 색 규칙
B5: 파란 글씨 = 직접 입력하는 칸 · 검정 글씨 = 수식(수정 금지) · 노란 칸 = 핵심 설정값 · 파란 헤더 = 입력 시트 열 · 남색 헤더 = 자동 계산 열
B7: ■ 처음 시작할 때 (1회, 약 1시간)
B8: 1. [계좌] 가족의 모든 계좌·자산·부채를 등록 (계좌ID는 A01, I01처럼 짧고 고유하게)
B9: 2. [스냅샷] 지난달 말 기준 계좌별 잔액 입력 → 재무상태표·순자산이 바로 나옵니다
B10: 3. [예산] 카테고리별 월 예산(비정기비는 연 예산) 확정 - 부부가 함께 정하세요
B11: 4. [투자] 보유 종목·목표 자산배분, [부채] 대출 금리·만기, [목표] 재무 목표, [보험] 보장 내역 입력
B12: 5. [설정] 목표 저축률·비상자금 개월·월 투자 납입 목표 등 '경영 목표' 확인
B14: ■ 운영 리듬 (거버넌스)
B15: 주간 10분: 카드·은행 CSV 가져오기 → [거래내역]에서 '미분류' 카테고리 지정
... B37: 기준값(30%, 6개월, 40% 등)은 일반적인 가이드라인이며 [설정]에서 가정에 맞게 바꾸세요

Sheet 거래내역
A1: 일자 | B1: 월 | C1: 내용 | D1: 금액 | E1: 카테고리 | F1: 대분류 | G1: 필수 | H1: 구성원 | I1: 결제수단 | J1: 출처 | K1: 메모 | L1: 월번호 | N1: 금액은 항상 양수. 들어온 돈/나간 돈 구분은 카테고리의 대분류(소득·고정비…)가 결정합니다.
N2: 카드·은행 CSV는 `python -m household_finance import`로 자동 분류·중복제거 후 추가됩니다.

Sheet 스냅샷
A1: 월 | B1: 계좌ID | C1: 금액 | D1: 계좌명 | E1: 유형 | F1: 소유자 | G1: 유동성 | I1: 매월 말 계좌별 잔액을 기록 (부채도 양수로). `python -m household_finance new-month`로 다음 달 행을 자동 생성.

Sheet 계좌
A1: 계좌ID | B1: 계좌명 | C1: 기관 | D1: 유형 | E1: 소유자 | F1: 유동성 | G1: 메모 | I1: 유형: 현금성/투자/연금/부동산/기타자산/부채 · 유동성: 즉시(오늘 꺼낼 수 있음)/1년내/장기

Sheet 투자
A1: 📈 투자 포트폴리오
A2: 보유종목 표에 수량·현재가를 입력하면 자산배분·수익률이 계산됩니다. 구글 시트에서는 현재가에 =GOOGLEFINANCE(시세코드) 사용 가능.
A3: 자산군 | B3: 목표 비중 | C3: 평가금액 | D3: 현재 비중 | E3: 괴리(%p) | F3: 상태 | G3: 목표까지 조정금액 | H3: (알림용) | I3: 리밸런싱 알림은 가계 전체 포트폴리오 기준(대시보드 보기 '전체')에서만 표시됩니다.
A4: 국내주식 | B4: 0.2 | C4: =SUMIFS($K$27:$K$126,$F$27:$F$126,A4,$C$27:$C$126,설정!$B$5) -> 0 | D4: =IF($C$9=0,0,C4/$C$9) -> 0 | E4: =D4-B4 -> -0.2 | F4: =IF($C$9=0,"",IF(ABS(E4)>설정!$B$16,"⚠ 리밸런싱","✅ 적정")) | G4: =B4*$C$9-C4 -> 0 | H4: =IF(ISNUMBER(SEARCH("리밸런싱",F4)),A4&" "&TEXT(E4,"+0%;-0%"),"")
A5: 해외주식 | B5: 0.45 | C5: =SUMIFS($K$27:$K$126,$F$27:$F$126,A5,$C$27:$C$126,설정!$B$5) -> 0 | D5: =IF($C$9=0,0,C5/$C$9) -> 0 | E5: =D5-B5 -> -0.45 | F5: =IF($C$9=0,"",IF(ABS(E5)>설정!$B$16,"⚠ 리밸런싱","✅ 적정")) | G5: =B5*$C$9-C5 -> 0 | H5: =IF(ISNUMBER(SEARCH("리밸런싱",F5)),A5&" "&TEXT(E5,"+0%;-0%"),"")
A6: 채권 | B6: 0.2 | C6: =SUMIFS($K$27:$K$126,$F$27:$F$126,A6,$C$27:$C$126,설정!$B$5) -> 0 | D6: =IF($C$9=0,0,C6/$C$9) -> 0 | E6: =D6-B6 -> -0.2 | F6: =IF($C$9=0,"",IF(ABS(E6)>설정!$B$16,"⚠ 리밸런싱","✅ 적정")) | G6: =B6*$C$9-C6 -> 0 | H6: =IF(ISNUMBER(SEARCH("리밸런싱",F6)),A6&" "&TEXT(E6,"+0%;-0%"),"")
A7: 현금성 | B7: 0.1 | C7: =SUMIFS($K$27:$K$126,$F$27:$F$126,A7,$C$27:$C$126,설정!$B$5) -> 0 | D7: =IF($C$9=0,0,C7/$C$9) -> 0 | E7: =D7-B7 -> -0.1 | F7: =IF($C$9=0,"",IF(ABS(E7)>설정!$B$16,"⚠ 리밸런싱","✅ 적정")) | G7: =B7*$C$9-C7 -> 0 | H7: =IF(ISNUMBER(SEARCH("리밸런싱",F7)),A7&" "&TEXT(E7,"+0%;-0%"),"")
A8: 대체투자 | B8: 0.05 | C8: =SUMIFS($K$27:$K$126,$F$27:$F$126,A8,$C$27:$C$126,설정!$B$5) -> 0 | D8: =IF($C$9=0,0,C8/$C$9) -> 0 | E8: =D8-B8 -> -0.05 | F8: =IF($C$9=0,"",IF(ABS(E8)>설정!$B$16,"⚠ 리밸런싱","✅ 적정")) | G8: =B8*$C$9-C8 -> 0 | H8: =IF(ISNUMBER(SEARCH("리밸런싱",F8)),A8&" "&TEXT(E8,"+0%;-0%"),"")
A9: 합계 | B9: =SUM(B4:B8) -> 1 | C9: =SUM(C4:C8) -> 0 | D9: =SUM(D4:D8) -> 0 | E9: =IF(ROUND(B9,4)<>1,"⚠ 목표 비중 합이 100%가 아님","")
A11: 투자금 확대 트래킹 | B11: 실적 | C11: 목표/전월 | D11: 달성률/증가율
A12: 이번 달 투자 납입액 | B12: =손익!M45 -> 0 | C12: =설정!$B$29 -> 2200000 | D12: =IF(C12=0,0,B12/C12) -> 0
A13: 최근 12개월 누적 납입 | B13: =손익!N45 -> 0 | C13: =설정!$B$29*12 -> 26400000 | D13: =IF(C13=0,0,B13/C13) -> 0
A14: 월평균 납입 (12개월) | B14: =손익!O45 -> 0 | C14: =설정!$B$29 -> 2200000 | D14: =IF(C14=0,0,B14/C14) -> 0
A15: 투자+연금 자산 (기준월) | B15: =재무상태표!B13 -> 0 | C15: =재무상태표!C13 -> 0 | D15: =IF(C15=0,0,B15/C15-1) -> 0
A16: 자산 증가 중 운용수익 (추정) | B16: =재무상태표!D13-B12 -> 0 | E16: 증감 − 이번 달 납입. 퇴직연금 회사 적립분 등이 섞일 수 있어 추정치입니다.
A18: 절세 계좌 납입 현황 (올해 1월~기준월, 거래내역 '내용' 키워드로 집계)
A19: 항목 | B19: 연간 한도 | C19: 올해 납입 | D19: 잔여 한도 | E19: 소진율 | F19: 내용 키워드
A20: 연금저축 | B20: =설정!$B$23 -> 6000000 | C20: =SUMIFS(거래내역!$D$2:$D$5000,거래내역!$L$2:$L$5000,">="&설정!$B$8,거래내역!$L$2:$L$5000,"<="&설정!$B$7,거래내역!$C$2:$C$5000,F20,거래내역!$H$2:$H$5000,설정!$B$5) -> 0 | D20: =MAX(0,B20-C20) -> 6000000 | E20: =IF(B20=0,0,C20/B20) -> 0 | F20: *연금저축*
A21: 연금저축+IRP 합산 | B21: =설정!$B$22 -> 9000000 | C21: =C20+SUMIFS(거래내역!$D$2:$D$5000,거래내역!$L$2:$L$5000,">="&설정!$B$8,거래내역!$L$2:$L$5000,"<="&설정!$B$7,거래내역!$C$2:$C$5000,F21,거래내역!$H$2:$H$5000,설정!$B$5) -> 0 | D21: =MAX(0,B21-C21) -> 9000000 | E21: =IF(B21=0,0,C21/B21) -> 0 | F21: *IRP*
A22: ISA | B22: =설정!$B$24 -> 20000000 | C22: =SUMIFS(거래내역!$D$2:$D$5000,거래내역!$L$2:$L$5000,">="&설정!$B$8,거래내역!$L$2:$L$5000,"<="&설정!$B$7,거래내역!$C$2:$C$5000,F22,거래내역!$H$2:$H$5000,설정!$B$5) -> 0 | D22: =MAX(0,B22-C22) -> 20000000 | E22: =IF(B22=0,0,C22/B22) -> 0 | F22: *ISA*
A23: '연금저축+IRP 합산'의 키워드 칸은 IRP 납입을 찾는 키워드입니다 (연금저축분은 위 행 값을 더함).
A24: 보유 종목 (파란 글씨 열 입력)
A25: 계좌ID | B25: 계좌명 | C25: 소유자 | D25: 종목명 | E25: 시세코드 | F25: 자산군 | G25: 수량 | H25: 평균단가 | I25: 현재가 | J25: 매입금액 | K25: 평가금액 | L25: 평가손익 | M25: 수익률
A26: 보유종목 합계 (보기 기준) | J26: =SUMIFS(J27:J126,$C$27:$C$126,설정!$B$5) -> 0 | K26: =SUMIFS(K27:K126,$C$27:$C$126,설정!$B$5) -> 0 | L26: =SUMIFS(L27:L126,$C$27:$C$126,설정!$B$5) -> 0 | M26: =IF(J26=0,0,L26/J26) -> 0
B27: =IF(A27="","",IFERROR(INDEX(계좌!$B$2:$B$41,MATCH(A27,계좌!$A$2:$A$41,0)),"?")) | C27: =IF(A27="","",IFERROR(INDEX(계좌!$E$2:$E$41,MATCH(A27,계좌!$A$2:$A$41,0)),"?")) | J27: =IF(A27="","",G27*H27) | K27: =IF(A27="","",G27*I27) | L27: =IF(A27="","",K27-J27) | M27: =IF(OR(A27="",N(J27)=0),"",L27/J27)
B28: =IF(A28="","",IFERROR(INDEX(계좌!$B$2:$B$41,MATCH(A28,계좌!$A$2:$A$41,0)),"?")) | C28: =IF(A28="","",IFERROR(INDEX(계좌!$E$2:$E$41,MATCH(A28,계좌!$A$2:$A$41,0)),"?")) | J28: =IF(A28="","",G28*H28) | K28: =IF(A28="","",G28*I28) | L28: =IF(A28="","",K28-J28) | M28: =IF(OR(A28="",N(J28)=0),"",L28/J28)
B29: =IF(A29="","",IFERROR(INDEX(계좌!$B$2:$B$41,MATCH(A29,계좌!$A$2:$A$41,0)),"?")) | C29: =IF(A29="","",IFERROR(INDEX(계좌!$E$2:$E$41,MATCH(A29,계좌!$A$2:$A$41,0)),"?")) | J29: =IF(A29="","",G29*H29) | K29: =IF(A29="","",G29*I29) | L29: =IF(A29="","",K29-J29) | M29: =IF(OR(A29="",N(J29)=0),"",L29/J29)
B30: =IF(A30="","",IFERROR(INDEX(계좌!$B$2:$B$41,MATCH(A30,계좌!$A$2:$A$41,0)),"?")) | C30: =IF(A30="","",IFERROR(INDEX(계좌!$E$2:$E$41,MATCH(A30,계좌!$A$2:$A$41,0)),"?")) | J30: =IF(A30="","",G30*H30) | K30: =IF(A30="","",G30*I30) | L30: =IF(A30="","",K30-J30) | M30: =IF(OR(A30="",N(J30)=0),"",L30/J30)
B31: =IF(A31="","",IFERROR(INDEX(계좌!$B$2:$B$41,MATCH(A31,계좌!$A$2:$A$41,0)),"?")) | C31: =IF(A31="","",IFERROR(INDEX(계좌!$E$2:$E$41,MATCH(A31,계좌!$A$2:$A$41,0)),"?")) | J31: =IF(A31="","",G31*H31) | K31: =IF(A31="","",G31*I31) | L31: =IF(A31="","",K31-J31) | M31: =IF(OR(A31="",N(J31)=0),"",L31/J31)
B32: =IF(A32="","",IFERROR(INDEX(계좌!$B$2:$B$41,MATCH(A32,계좌!$A$2:$A$41,0)),"?")) | C32: =IF(A32="","",IFERROR(INDEX(계좌!$E$2:$E$41,MATCH(A32,계좌!$A$2:$A$41,0)),"?")) | J32: =IF(A32="","",G32*H32) | K32: =IF(A32="","",G32*I32) | L32: =IF(A32="","",K32-J32) | M32: =IF(OR(A32="",N(J32)=0),"",L32/J32)
B33: =IF(A33="","",IFERROR(INDEX(계좌!$B$2:$B$41,MATCH(A33,계좌!$A$2:$A$41,0)),"?")) | C33: =IF(A33="","",IFERROR(INDEX(계좌!$E$2:$E$41,MATCH(A33,계좌!$A$2:$A$41,0)),"?")) | J33: =IF(A33="","",G33*H33) | K33: =IF(A33="","",G33*I33) | L33: =IF(A33="","",K33-J33) | M33: =IF(OR(A33="",N(J33)=0),"",L33/J33)
B34: =IF(A34="","",IFERROR(INDEX(계좌!$B$2:$B$41,MATCH(A34,계좌!$A$2:$A$41,0)),"?")) | C34: =IF(A34="","",IFERROR(INDEX(계좌!$E$2:$E$41,MATCH(A34,계좌!$A$2:$A$41,0)),"?")) | J34: =IF(A34="","",G34*H34) | K34: =IF(A34="","",G34*I34) | L34: =IF(A34="","",K34-J34) | M34: =IF(OR(A34="",N(J34)=0),"",L34/J34)
B35: =IF(A35="","",IFERROR(INDEX(계좌!$B$2:$B$41,MATCH(A35,계좌!$A$2:$A$41,0)),"?")) | C35: =IF(A35="","",IFERROR(INDEX(계좌!$E$2:$E$41,MATCH(A35,계좌!$A$2:$A$41,0)),"?")) | J35: =IF(A35="","",G35*H35) | K35: =IF(A35="","",G35*I35) | L35: =IF(A35="","",K35-J35) | M35: =IF(OR(A35="",N(J35)=0),"",L35/J35)
B36: =IF(A36="","",IFERROR(INDEX(계좌!$B$2:$B$41,MATCH(A36,계좌!$A$2:$A$41,0)),"?")) | C36: =IF(A36="","",IFERROR(INDEX(계좌!$E$2:$E$41,MATCH(A36,계좌!$A$2:$A$41,0)),"?")) | J36: =IF(A36="","",G36*H36) | K36: =IF(A36="","",G36*I36) | L36: =IF(A36="","",K36-J36) | M36: =IF(OR(A36="",N(J36)=0),"",L36/J36)
B37: =IF(A37="","",IFERROR(INDEX(계좌!$B$2:$B$41,MATCH(A37,계좌!$A$2:$A$41,0)),"?")) | C37: =IF(A37="","",IFERROR(INDEX(계좌!$E$2:$E$41,MATCH(A37,계좌!$A$2:$A$41,0)),"?")) | J37: =IF(A37="","",G37*H37) | K37: =IF(A37="","",G37*I37) | L37: =IF(A37="","",K37-J37) | M37: =IF(OR(A37="",N(J37)=0),"",L37/J37)
B38: =IF(A38="","",IFERROR(INDEX(계좌!$B$2:$B$41,MATCH(A38,계좌!$A$2:$A$41,0)),"?")) | C38: =IF(A38="","",IFERROR(INDEX(계좌!$E$2:$E$41,MATCH(A38,계좌!$A$2:$A$41,0)),"?")) | J38: =IF(A38="","",G38*H38) | K38: =IF(A38="","",G38*I38) | L38: =IF(A38="","",K38-J38) | M38: =IF(OR(A38="",N(J38)=0),"",L38/J38)
... B126: =IF(A126="","",IFERROR(INDEX(계좌!$B$2:$B$41,MATCH(A126,계좌!$A$2:$A$41,0)),"?")) | C126: =IF(A126="","",IFERROR(INDEX(계좌!$E$2:$E$41,MATCH(A126,계좌!$A$2:$A$41,0)),"?")) | J126: =IF(A126="","",G126*H126) | K126: =IF(A126="","",G126*I126) | L126: =IF(A126="","",K126-J126) | M126: =IF(OR(A126="",N(J126)=0),"",L126/J126)

Sheet 부채
A1: 💳 부채 관리
A2: 잔액은 스냅샷 기준월 값을 자동으로 가져옵니다. 상환 우선순위는 금리가 높은 순.
A3: 대출명 | B3: 계좌ID | C3: 소유자 | D3: 잔액(기준월) | E3: 금리(연) | F3: 만기일 | G3: 상환방식 | H3: 월 원리금 | I3: 월 이자(추정) | J3: 연간 원리금 | K3: 금리 +1%p 시 월 증가 | L3: 남은 개월 | M3: 상환 우선순위
C4: =IF(B4="","",IFERROR(INDEX(계좌!$E$2:$E$41,MATCH(B4,계좌!$A$2:$A$41,0)),"?")) | D4: =IF(B4="","",SUMIFS(스냅샷!$C$2:$C$3000,스냅샷!$A$2:$A$3000,설정!$B$3,스냅샷!$B$2:$B$3000,B4)) | I4: =IF(B4="","",D4*E4/12) | J4: =IF(B4="","",H4*12) | K4: =IF(B4="","",D4*0.01/12) | L4: =IF(F4="","",MAX(0,ROUND((F4-설정!$B$10)/30.4,0))) | M4: =IF(OR(B4="",E4=""),"",RANK(E4,$E$4:$E$13))
C5: =IF(B5="","",IFERROR(INDEX(계좌!$E$2:$E$41,MATCH(B5,계좌!$A$2:$A$41,0)),"?")) | D5: =IF(B5="","",SUMIFS(스냅샷!$C$2:$C$3000,스냅샷!$A$2:$A$3000,설정!$B$3,스냅샷!$B$2:$B$3000,B5)) | I5: =IF(B5="","",D5*E5/12) | J5: =IF(B5="","",H5*12) | K5: =IF(B5="","",D5*0.01/12) | L5: =IF(F5="","",MAX(0,ROUND((F5-설정!$B$10)/30.4,0))) | M5: =IF(OR(B5="",E5=""),"",RANK(E5,$E$4:$E$13))
C6: =IF(B6="","",IFERROR(INDEX(계좌!$E$2:$E$41,MATCH(B6,계좌!$A$2:$A$41,0)),"?")) | D6: =IF(B6="","",SUMIFS(스냅샷!$C$2:$C$3000,스냅샷!$A$2:$A$3000,설정!$B$3,스냅샷!$B$2:$B$3000,B6)) | I6: =IF(B6="","",D6*E6/12) | J6: =IF(B6="","",H6*12) | K6: =IF(B6="","",D6*0.01/12) | L6: =IF(F6="","",MAX(0,ROUND((F6-설정!$B$10)/30.4,0))) | M6: =IF(OR(B6="",E6=""),"",RANK(E6,$E$4:$E$13))
C7: =IF(B7="","",IFERROR(INDEX(계좌!$E$2:$E$41,MATCH(B7,계좌!$A$2:$A$41,0)),"?")) | D7: =IF(B7="","",SUMIFS(스냅샷!$C$2:$C$3000,스냅샷!$A$2:$A$3000,설정!$B$3,스냅샷!$B$2:$B$3000,B7)) | I7: =IF(B7="","",D7*E7/12) | J7: =IF(B7="","",H7*12) | K7: =IF(B7="","",D7*0.01/12) | L7: =IF(F7="","",MAX(0,ROUND((F7-설정!$B$10)/30.4,0))) | M7: =IF(OR(B7="",E7=""),"",RANK(E7,$E$4:$E$13))
C8: =IF(B8="","",IFERROR(INDEX(계좌!$E$2:$E$41,MATCH(B8,계좌!$A$2:$A$41,0)),"?")) | D8: =IF(B8="","",SUMIFS(스냅샷!$C$2:$C$3000,스냅샷!$A$2:$A$3000,설정!$B$3,스냅샷!$B$2:$B$3000,B8)) | I8: =IF(B8="","",D8*E8/12) | J8: =IF(B8="","",H8*12) | K8: =IF(B8="","",D8*0.01/12) | L8: =IF(F8="","",MAX(0,ROUND((F8-설정!$B$10)/30.4,0))) | M8: =IF(OR(B8="",E8=""),"",RANK(E8,$E$4:$E$13))
C9: =IF(B9="","",IFERROR(INDEX(계좌!$E$2:$E$41,MATCH(B9,계좌!$A$2:$A$41,0)),"?")) | D9: =IF(B9="","",SUMIFS(스냅샷!$C$2:$C$3000,스냅샷!$A$2:$A$3000,설정!$B$3,스냅샷!$B$2:$B$3000,B9)) | I9: =IF(B9="","",D9*E9/12) | J9: =IF(B9="","",H9*12) | K9: =IF(B9="","",D9*0.01/12) | L9: =IF(F9="","",MAX(0,ROUND((F9-설정!$B$10)/30.4,0))) | M9: =IF(OR(B9="",E9=""),"",RANK(E9,$E$4:$E$13))
C10: =IF(B10="","",IFERROR(INDEX(계좌!$E$2:$E$41,MATCH(B10,계좌!$A$2:$A$41,0)),"?")) | D10: =IF(B10="","",SUMIFS(스냅샷!$C$2:$C$3000,스냅샷!$A$2:$A$3000,설정!$B$3,스냅샷!$B$2:$B$3000,B10)) | I10: =IF(B10="","",D10*E10/12) | J10: =IF(B10="","",H10*12) | K10: =IF(B10="","",D10*0.01/12) | L10: =IF(F10="","",MAX(0,ROUND((F10-설정!$B$10)/30.4,0))) | M10: =IF(OR(B10="",E10=""),"",RANK(E10,$E$4:$E$13))
C11: =IF(B11="","",IFERROR(INDEX(계좌!$E$2:$E$41,MATCH(B11,계좌!$A$2:$A$41,0)),"?")) | D11: =IF(B11="","",SUMIFS(스냅샷!$C$2:$C$3000,스냅샷!$A$2:$A$3000,설정!$B$3,스냅샷!$B$2:$B$3000,B11)) | I11: =IF(B11="","",D11*E11/12) | J11: =IF(B11="","",H11*12) | K11: =IF(B11="","",D11*0.01/12) | L11: =IF(F11="","",MAX(0,ROUND((F11-설정!$B$10)/30.4,0))) | M11: =IF(OR(B11="",E11=""),"",RANK(E11,$E$4:$E$13))
C12: =IF(B12="","",IFERROR(INDEX(계좌!$E$2:$E$41,MATCH(B12,계좌!$A$2:$A$41,0)),"?")) | D12: =IF(B12="","",SUMIFS(스냅샷!$C$2:$C$3000,스냅샷!$A$2:$A$3000,설정!$B$3,스냅샷!$B$2:$B$3000,B12)) | I12: =IF(B12="","",D12*E12/12) | J12: =IF(B12="","",H12*12) | K12: =IF(B12="","",D12*0.01/12) | L12: =IF(F12="","",MAX(0,ROUND((F12-설정!$B$10)/30.4,0))) | M12: =IF(OR(B12="",E12=""),"",RANK(E12,$E$4:$E$13))
C13: =IF(B13="","",IFERROR(INDEX(계좌!$E$2:$E$41,MATCH(B13,계좌!$A$2:$A$41,0)),"?")) | D13: =IF(B13="","",SUMIFS(스냅샷!$C$2:$C$3000,스냅샷!$A$2:$A$3000,설정!$B$3,스냅샷!$B$2:$B$3000,B13)) | I13: =IF(B13="","",D13*E13/12) | J13: =IF(B13="","",H13*12) | K13: =IF(B13="","",D13*0.01/12) | L13: =IF(F13="","",MAX(0,ROUND((F13-설정!$B$10)/30.4,0))) | M13: =IF(OR(B13="",E13=""),"",RANK(E13,$E$4:$E$13))
A15: 요약
A16: 총 대출잔액 (보기 기준) | B16: =SUMIFS(D4:D13,C4:C13,설정!$B$5) -> 0
A17: 월 원리금 합계 | B17: =SUMIFS(H4:H13,C4:C13,설정!$B$5) -> 0
A18: 연간 원리금 | B18: =B17*12 -> 0
A19: 연소득 (최근 12개월 · 공동 보기는 가계 전체) | B19: =IF(설정!$B$4="공동",SUMIFS(거래내역!$D$2:$D$5000,거래내역!$F$2:$F$5000,"소득",거래내역!$L$2:$L$5000,">="&VALUE(SUBSTITUTE(TEXT(EDATE(DATEVALUE(설정!$B$3&"-01"),-11),"yyyy-mm"),"-","")),거래내역!$L$2:$L$5000,"<="&설정!$B$7),손익!N9) -> 0
A20: DSR (연간 원리금/연소득) | B20: =IF(B19=0,0,B18/B19) -> 0 | C20: =IF(B20>B21,"⚠ 상한 초과","✅ 양호") -> ✅ 양호
A21: DSR 상한 (설정) | B21: =설정!$B$15 -> 0.3
A22: 금리 1%p 상승 시 월 부담 증가 | B22: =SUMIFS(K4:K13,C4:C13,설정!$B$5) -> 0
A23: 가중평균 금리 | B23: =IF(SUM(D4:D13)=0,0,SUMPRODUCT(D4:D13,E4:E13)/SUM(D4:D13)) -> 0

Sheet 목표
A1: 🎯 재무 목표 (중장기 사업계획)
A2: 연결계좌의 기준월 잔액 합으로 진척률을 계산합니다. 계획 진척률 = 시작일~목표일 중 오늘까지 경과 비율.
A3: 목표명 | B3: 담당 | C3: 목표금액 | D3: 시작일 | E3: 목표일 | F3: 연결계좌1 | G3: 연결계좌2 | H3: 연결계좌3 | I3: 현재금액 | J3: 진척률 | K3: 계획 진척률 | L3: 상태 | M3: 남은 개월 | N3: 필요 월적립액 | O3: (진척 반영액) | P3: (알림용)
A4: 비상자금 | B4: 공동 | C4: =ROUND(설정!$B$13*손익!P49,-4) -> 0 | D4: 46306 | E4: 46671 | I4: =IF(A4="","",IF(F4="",0,SUMIFS(스냅샷!$C$2:$C$3000,스냅샷!$A$2:$A$3000,설정!$B$3,스냅샷!$B$2:$B$3000,F4))+IF(G4="",0,SUMIFS(스냅샷!$C$2:$C$3000,스냅샷!$A$2:$A$3000,설정!$B$3,스냅샷!$B$2:$B$3000,G4))+IF(H4="",0,SUMIFS(스냅샷!$C$2:$C$3000,스냅샷!$A$2:$A$3000,설정!$B$3,스냅샷!$B$2:$B$3000,H4))) -> 0 | J4: =IF(OR(A4="",N(C4)=0),"",MIN(1,I4/C4)) | K4: =IF(OR(A4="",D4="",E4=""),"",IF(E4<=D4,1,MAX(0,MIN(1,(설정!$B$10-D4)/(E4-D4))))) -> 0 | L4: =IF(OR(A4="",J4=""),"",IF(J4>=1,"🎉 달성",IF(J4>=K4-설정!$B$20,"✅ 순항","⚠ 지연"))) | M4: =IF(OR(A4="",E4=""),"",MAX(1,ROUND((E4-설정!$B$10)/30.4,0))) -> 12 | N4: =IF(OR(A4="",M4=""),"",MAX(0,(C4-I4)/M4)) -> 0 | O4: =IF(A4="",0,MIN(N(I4),N(C4))) -> 0 | P4: =IF(ISNUMBER(SEARCH("지연",L4)),A4&" "&TEXT(J4,"0%"),"")
I5: =IF(A5="","",IF(F5="",0,SUMIFS(스냅샷!$C$2:$C$3000,스냅샷!$A$2:$A$3000,설정!$B$3,스냅샷!$B$2:$B$3000,F5))+IF(G5="",0,SUMIFS(스냅샷!$C$2:$C$3000,스냅샷!$A$2:$A$3000,설정!$B$3,스냅샷!$B$2:$B$3000,G5))+IF(H5="",0,SUMIFS(스냅샷!$C$2:$C$3000,스냅샷!$A$2:$A$3000,설정!$B$3,스냅샷!$B$2:$B$3000,H5))) | J5: =IF(OR(A5="",N(C5)=0),"",MIN(1,I5/C5)) | K5: =IF(OR(A5="",D5="",E5=""),"",IF(E5<=D5,1,MAX(0,MIN(1,(설정!$B$10-D5)/(E5-D5))))) | L5: =IF(OR(A5="",J5=""),"",IF(J5>=1,"🎉 달성",IF(J5>=K5-설정!$B$20,"✅ 순항","⚠ 지연"))) | M5: =IF(OR(A5="",E5=""),"",MAX(1,ROUND((E5-설정!$B$10)/30.4,0))) | N5: =IF(OR(A5="",M5=""),"",MAX(0,(C5-I5)/M5)) | O5: =IF(A5="",0,MIN(N(I5),N(C5))) -> 0 | P5: =IF(ISNUMBER(SEARCH("지연",L5)),A5&" "&TEXT(J5,"0%"),"")
I6: =IF(A6="","",IF(F6="",0,SUMIFS(스냅샷!$C$2:$C$3000,스냅샷!$A$2:$A$3000,설정!$B$3,스냅샷!$B$2:$B$3000,F6))+IF(G6="",0,SUMIFS(스냅샷!$C$2:$C$3000,스냅샷!$A$2:$A$3000,설정!$B$3,스냅샷!$B$2:$B$3000,G6))+IF(H6="",0,SUMIFS(스냅샷!$C$2:$C$3000,스냅샷!$A$2:$A$3000,설정!$B$3,스냅샷!$B$2:$B$3000,H6))) | J6: =IF(OR(A6="",N(C6)=0),"",MIN(1,I6/C6)) | K6: =IF(OR(A6="",D6="",E6=""),"",IF(E6<=D6,1,MAX(0,MIN(1,(설정!$B$10-D6)/(E6-D6))))) | L6: =IF(OR(A6="",J6=""),"",IF(J6>=1,"🎉 달성",IF(J6>=K6-설정!$B$20,"✅ 순항","⚠ 지연"))) | M6: =IF(OR(A6="",E6=""),"",MAX(1,ROUND((E6-설정!$B$10)/30.4,0))) | N6: =IF(OR(A6="",M6=""),"",MAX(0,(C6-I6)/M6)) | O6: =IF(A6="",0,MIN(N(I6),N(C6))) -> 0 | P6: =IF(ISNUMBER(SEARCH("지연",L6)),A6&" "&TEXT(J6,"0%"),"")
I7: =IF(A7="","",IF(F7="",0,SUMIFS(스냅샷!$C$2:$C$3000,스냅샷!$A$2:$A$3000,설정!$B$3,스냅샷!$B$2:$B$3000,F7))+IF(G7="",0,SUMIFS(스냅샷!$C$2:$C$3000,스냅샷!$A$2:$A$3000,설정!$B$3,스냅샷!$B$2:$B$3000,G7))+IF(H7="",0,SUMIFS(스냅샷!$C$2:$C$3000,스냅샷!$A$2:$A$3000,설정!$B$3,스냅샷!$B$2:$B$3000,H7))) | J7: =IF(OR(A7="",N(C7)=0),"",MIN(1,I7/C7)) | K7: =IF(OR(A7="",D7="",E7=""),"",IF(E7<=D7,1,MAX(0,MIN(1,(설정!$B$10-D7)/(E7-D7))))) | L7: =IF(OR(A7="",J7=""),"",IF(J7>=1,"🎉 달성",IF(J7>=K7-설정!$B$20,"✅ 순항","⚠ 지연"))) | M7: =IF(OR(A7="",E7=""),"",MAX(1,ROUND((E7-설정!$B$10)/30.4,0))) | N7: =IF(OR(A7="",M7=""),"",MAX(0,(C7-I7)/M7)) | O7: =IF(A7="",0,MIN(N(I7),N(C7))) -> 0 | P7: =IF(ISNUMBER(SEARCH("지연",L7)),A7&" "&TEXT(J7,"0%"),"")
I8: =IF(A8="","",IF(F8="",0,SUMIFS(스냅샷!$C$2:$C$3000,스냅샷!$A$2:$A$3000,설정!$B$3,스냅샷!$B$2:$B$3000,F8))+IF(G8="",0,SUMIFS(스냅샷!$C$2:$C$3000,스냅샷!$A$2:$A$3000,설정!$B$3,스냅샷!$B$2:$B$3000,G8))+IF(H8="",0,SUMIFS(스냅샷!$C$2:$C$3000,스냅샷!$A$2:$A$3000,설정!$B$3,스냅샷!$B$2:$B$3000,H8))) | J8: =IF(OR(A8="",N(C8)=0),"",MIN(1,I8/C8)) | K8: =IF(OR(A8="",D8="",E8=""),"",IF(E8<=D8,1,MAX(0,MIN(1,(설정!$B$10-D8)/(E8-D8))))) | L8: =IF(OR(A8="",J8=""),"",IF(J8>=1,"🎉 달성",IF(J8>=K8-설정!$B$20,"✅ 순항","⚠ 지연"))) | M8: =IF(OR(A8="",E8=""),"",MAX(1,ROUND((E8-설정!$B$10)/30.4,0))) | N8: =IF(OR(A8="",M8=""),"",MAX(0,(C8-I8)/M8)) | O8: =IF(A8="",0,MIN(N(I8),N(C8))) -> 0 | P8: =IF(ISNUMBER(SEARCH("지연",L8)),A8&" "&TEXT(J8,"0%"),"")
I9: =IF(A9="","",IF(F9="",0,SUMIFS(스냅샷!$C$2:$C$3000,스냅샷!$A$2:$A$3000,설정!$B$3,스냅샷!$B$2:$B$3000,F9))+IF(G9="",0,SUMIFS(스냅샷!$C$2:$C$3000,스냅샷!$A$2:$A$3000,설정!$B$3,스냅샷!$B$2:$B$3000,G9))+IF(H9="",0,SUMIFS(스냅샷!$C$2:$C$3000,스냅샷!$A$2:$A$3000,설정!$B$3,스냅샷!$B$2:$B$3000,H9))) | J9: =IF(OR(A9="",N(C9)=0),"",MIN(1,I9/C9)) | K9: =IF(OR(A9="",D9="",E9=""),"",IF(E9<=D9,1,MAX(0,MIN(1,(설정!$B$10-D9)/(E9-D9))))) | L9: =IF(OR(A9="",J9=""),"",IF(J9>=1,"🎉 달성",IF(J9>=K9-설정!$B$20,"✅ 순항","⚠ 지연"))) | M9: =IF(OR(A9="",E9=""),"",MAX(1,ROUND((E9-설정!$B$10)/30.4,0))) | N9: =IF(OR(A9="",M9=""),"",MAX(0,(C9-I9)/M9)) | O9: =IF(A9="",0,MIN(N(I9),N(C9))) -> 0 | P9: =IF(ISNUMBER(SEARCH("지연",L9)),A9&" "&TEXT(J9,"0%"),"")
I10: =IF(A10="","",IF(F10="",0,SUMIFS(스냅샷!$C$2:$C$3000,스냅샷!$A$2:$A$3000,설정!$B$3,스냅샷!$B$2:$B$3000,F10))+IF(G10="",0,SUMIFS(스냅샷!$C$2:$C$3000,스냅샷!$A$2:$A$3000,설정!$B$3,스냅샷!$B$2:$B$3000,G10))+IF(H10="",0,SUMIFS(스냅샷!$C$2:$C$3000,스냅샷!$A$2:$A$3000,설정!$B$3,스냅샷!$B$2:$B$3000,H10))) | J10: =IF(OR(A10="",N(C10)=0),"",MIN(1,I10/C10)) | K10: =IF(OR(A10="",D10="",E10=""),"",IF(E10<=D10,1,MAX(0,MIN(1,(설정!$B$10-D10)/(E10-D10))))) | L10: =IF(OR(A10="",J10=""),"",IF(J10>=1,"🎉 달성",IF(J10>=K10-설정!$B$20,"✅ 순항","⚠ 지연"))) | M10: =IF(OR(A10="",E10=""),"",MAX(1,ROUND((E10-설정!$B$10)/30.4,0))) | N10: =IF(OR(A10="",M10=""),"",MAX(0,(C10-I10)/M10)) | O10: =IF(A10="",0,MIN(N(I10),N(C10))) -> 0 | P10: =IF(ISNUMBER(SEARCH("지연",L10)),A10&" "&TEXT(J10,"0%"),"")
I11: =IF(A11="","",IF(F11="",0,SUMIFS(스냅샷!$C$2:$C$3000,스냅샷!$A$2:$A$3000,설정!$B$3,스냅샷!$B$2:$B$3000,F11))+IF(G11="",0,SUMIFS(스냅샷!$C$2:$C$3000,스냅샷!$A$2:$A$3000,설정!$B$3,스냅샷!$B$2:$B$3000,G11))+IF(H11="",0,SUMIFS(스냅샷!$C$2:$C$3000,스냅샷!$A$2:$A$3000,설정!$B$3,스냅샷!$B$2:$B$3000,H11))) | J11: =IF(OR(A11="",N(C11)=0),"",MIN(1,I11/C11)) | K11: =IF(OR(A11="",D11="",E11=""),"",IF(E11<=D11,1,MAX(0,MIN(1,(설정!$B$10-D11)/(E11-D11))))) | L11: =IF(OR(A11="",J11=""),"",IF(J11>=1,"🎉 달성",IF(J11>=K11-설정!$B$20,"✅ 순항","⚠ 지연"))) | M11: =IF(OR(A11="",E11=""),"",MAX(1,ROUND((E11-설정!$B$10)/30.4,0))) | N11: =IF(OR(A11="",M11=""),"",MAX(0,(C11-I11)/M11)) | O11: =IF(A11="",0,MIN(N(I11),N(C11))) -> 0 | P11: =IF(ISNUMBER(SEARCH("지연",L11)),A11&" "&TEXT(J11,"0%"),"")
I12: =IF(A12="","",IF(F12="",0,SUMIFS(스냅샷!$C$2:$C$3000,스냅샷!$A$2:$A$3000,설정!$B$3,스냅샷!$B$2:$B$3000,F12))+IF(G12="",0,SUMIFS(스냅샷!$C$2:$C$3000,스냅샷!$A$2:$A$3000,설정!$B$3,스냅샷!$B$2:$B$3000,G12))+IF(H12="",0,SUMIFS(스냅샷!$C$2:$C$3000,스냅샷!$A$2:$A$3000,설정!$B$3,스냅샷!$B$2:$B$3000,H12))) | J12: =IF(OR(A12="",N(C12)=0),"",MIN(1,I12/C12)) | K12: =IF(OR(A12="",D12="",E12=""),"",IF(E12<=D12,1,MAX(0,MIN(1,(설정!$B$10-D12)/(E12-D12))))) | L12: =IF(OR(A12="",J12=""),"",IF(J12>=1,"🎉 달성",IF(J12>=K12-설정!$B$20,"✅ 순항","⚠ 지연"))) | M12: =IF(OR(A12="",E12=""),"",MAX(1,ROUND((E12-설정!$B$10)/30.4,0))) | N12: =IF(OR(A12="",M12=""),"",MAX(0,(C12-I12)/M12)) | O12: =IF(A12="",0,MIN(N(I12),N(C12))) -> 0 | P12: =IF(ISNUMBER(SEARCH("지연",L12)),A12&" "&TEXT(J12,"0%"),"")
I13: =IF(A13="","",IF(F13="",0,SUMIFS(스냅샷!$C$2:$C$3000,스냅샷!$A$2:$A$3000,설정!$B$3,스냅샷!$B$2:$B$3000,F13))+IF(G13="",0,SUMIFS(스냅샷!$C$2:$C$3000,스냅샷!$A$2:$A$3000,설정!$B$3,스냅샷!$B$2:$B$3000,G13))+IF(H13="",0,SUMIFS(스냅샷!$C$2:$C$3000,스냅샷!$A$2:$A$3000,설정!$B$3,스냅샷!$B$2:$B$3000,H13))) | J13: =IF(OR(A13="",N(C13)=0),"",MIN(1,I13/C13)) | K13: =IF(OR(A13="",D13="",E13=""),"",IF(E13<=D13,1,MAX(0,MIN(1,(설정!$B$10-D13)/(E13-D13))))) | L13: =IF(OR(A13="",J13=""),"",IF(J13>=1,"🎉 달성",IF(J13>=K13-설정!$B$20,"✅ 순항","⚠ 지연"))) | M13: =IF(OR(A13="",E13=""),"",MAX(1,ROUND((E13-설정!$B$10)/30.4,0))) | N13: =IF(OR(A13="",M13=""),"",MAX(0,(C13-I13)/M13)) | O13: =IF(A13="",0,MIN(N(I13),N(C13))) -> 0 | P13: =IF(ISNUMBER(SEARCH("지연",L13)),A13&" "&TEXT(J13,"0%"),"")
A16: 전체 목표 가중 달성률 | B16: =IF(SUM(C4:C13)=0,0,SUM(O4:O13)/SUM(C4:C13)) -> 0
A17: 노후 준비율 ('노후'로 시작하는 목표) | B17: =IFERROR(INDEX(J4:J13,MATCH("노후*",A4:A13,0)),0) -> 0 | C17: 국민연금 예상수령액은 포함되지 않습니다 - 목표금액에서 차감해 입력하세요.
A18: 지연 목표 수 | B18: =COUNTIF(L4:L13,"*지연*") -> 0
A19: 목표 달성에 필요한 월 적립 합계 | B19: =SUM(N4:N13) -> 0

Sheet 보험
A1: 🛡 보험·리스크 관리
A2: 보장금액을 입력하면 구성원별 보장 공백을 자동으로 찾아냅니다 (0 또는 빈칸 = 보장 없음).
A3: 피보험자 | B3: 보험사 | C3: 상품명 | D3: 사망 | E3: 실손 | F3: 암 | G3: 뇌·심장 | H3: 배상책임 | I3: 월보험료 | J3: 만기일 | K3: 갱신형(Y/N)
A15: 구성원별 보장 현황
A16: 구성원 | B16: 사망 | C16: 실손 | D16: 암 | E16: 뇌·심장 | F16: 배상책임 | G16: 월보험료
A17: 본인 | B17: =IF(SUMIFS($D$4:$D$13,$A$4:$A$13,$A17)>0,"✅ "&TEXT(SUMIFS($D$4:$D$13,$A$4:$A$13,$A17)/10000,"#,##0")&"만","❌ 공백") -> ❌ 공백 | C17: =IF(SUMIFS($E$4:$E$13,$A$4:$A$13,$A17)>0,"✅ "&TEXT(SUMIFS($E$4:$E$13,$A$4:$A$13,$A17)/10000,"#,##0")&"만","❌ 공백") -> ❌ 공백 | D17: =IF(SUMIFS($F$4:$F$13,$A$4:$A$13,$A17)>0,"✅ "&TEXT(SUMIFS($F$4:$F$13,$A$4:$A$13,$A17)/10000,"#,##0")&"만","❌ 공백") -> ❌ 공백 | E17: =IF(SUMIFS($G$4:$G$13,$A$4:$A$13,$A17)>0,"✅ "&TEXT(SUMIFS($G$4:$G$13,$A$4:$A$13,$A17)/10000,"#,##0")&"만","❌ 공백") -> ❌ 공백 | F17: =IF(SUMIFS($H$4:$H$13,$A$4:$A$13,$A17)>0,"✅ "&TEXT(SUMIFS($H$4:$H$13,$A$4:$A$13,$A17)/10000,"#,##0")&"만","❌ 공백") -> ❌ 공백 | G17: =SUMIFS($I$4:$I$13,$A$4:$A$13,$A17) -> 0
A18: 배우자 | B18: =IF(SUMIFS($D$4:$D$13,$A$4:$A$13,$A18)>0,"✅ "&TEXT(SUMIFS($D$4:$D$13,$A$4:$A$13,$A18)/10000,"#,##0")&"만","❌ 공백") -> ❌ 공백 | C18: =IF(SUMIFS($E$4:$E$13,$A$4:$A$13,$A18)>0,"✅ "&TEXT(SUMIFS($E$4:$E$13,$A$4:$A$13,$A18)/10000,"#,##0")&"만","❌ 공백") -> ❌ 공백 | D18: =IF(SUMIFS($F$4:$F$13,$A$4:$A$13,$A18)>0,"✅ "&TEXT(SUMIFS($F$4:$F$13,$A$4:$A$13,$A18)/10000,"#,##0")&"만","❌ 공백") -> ❌ 공백 | E18: =IF(SUMIFS($G$4:$G$13,$A$4:$A$13,$A18)>0,"✅ "&TEXT(SUMIFS($G$4:$G$13,$A$4:$A$13,$A18)/10000,"#,##0")&"만","❌ 공백") -> ❌ 공백 | F18: =IF(SUMIFS($H$4:$H$13,$A$4:$A$13,$A18)>0,"✅ "&TEXT(SUMIFS($H$4:$H$13,$A$4:$A$13,$A18)/10000,"#,##0")&"만","❌ 공백") -> ❌ 공백 | G18: =SUMIFS($I$4:$I$13,$A$4:$A$13,$A18) -> 0
A19: 자녀 | B19: - | C19: =IF(SUMIFS($E$4:$E$13,$A$4:$A$13,$A19)>0,"✅ "&TEXT(SUMIFS($E$4:$E$13,$A$4:$A$13,$A19)/10000,"#,##0")&"만","❌ 공백") -> ❌ 공백 | D19: =IF(SUMIFS($F$4:$F$13,$A$4:$A$13,$A19)>0,"✅ "&TEXT(SUMIFS($F$4:$F$13,$A$4:$A$13,$A19)/10000,"#,##0")&"만","❌ 공백") -> ❌ 공백 | E19: =IF(SUMIFS($G$4:$G$13,$A$4:$A$13,$A19)>0,"✅ "&TEXT(SUMIFS($G$4:$G$13,$A$4:$A$13,$A19)/10000,"#,##0")&"만","❌ 공백") -> ❌ 공백 | F19: =IF(SUMIFS($H$4:$H$13,$A$4:$A$13,$A19)>0,"✅ "&TEXT(SUMIFS($H$4:$H$13,$A$4:$A$13,$A19)/10000,"#,##0")&"만","❌ 공백") -> ❌ 공백 | G19: =SUMIFS($I$4:$I$13,$A$4:$A$13,$A19) -> 0
A21: 월 보험료 합계 | B21: =SUM(I4:I13) -> 0
A22: 월평균 소득 (12개월) | B22: =손익!O9 -> 0
A23: 보험료 부담률 (권장 10% 이하) | B23: =IF(B22=0,0,B21/B22) -> 0
A24: 보장 공백 수 | B24: =COUNTIF(B17:F19,"*공백*") -> 14

Sheet 일정
A1: 🗓 일정 (현금흐름 이벤트 캘린더)
A2: 만기·세금·명절·보너스 등. 유입/유출 금액은 현금흐름 예측에 반영되고, 알림 일수 이내 일정은 대시보드에 표시됩니다.
A3: 일자 | B3: 내용 | C3: 구분 | D3: 금액 | E3: 구성원 | F3: 월 | G3: D-day | H3: 알림
F4: =IF(A4="","",TEXT(A4,"yyyy-mm")) | G4: =IF(A4="","",A4-설정!$B$10) | H4: =IF(A4="","",IF(AND(G4>=0,G4<=설정!$B$19),B4&" D-"&G4,""))
F5: =IF(A5="","",TEXT(A5,"yyyy-mm")) | G5: =IF(A5="","",A5-설정!$B$10) | H5: =IF(A5="","",IF(AND(G5>=0,G5<=설정!$B$19),B5&" D-"&G5,""))
F6: =IF(A6="","",TEXT(A6,"yyyy-mm")) | G6: =IF(A6="","",A6-설정!$B$10) | H6: =IF(A6="","",IF(AND(G6>=0,G6<=설정!$B$19),B6&" D-"&G6,""))
F7: =IF(A7="","",TEXT(A7,"yyyy-mm")) | G7: =IF(A7="","",A7-설정!$B$10) | H7: =IF(A7="","",IF(AND(G7>=0,G7<=설정!$B$19),B7&" D-"&G7,""))
F8: =IF(A8="","",TEXT(A8,"yyyy-mm")) | G8: =IF(A8="","",A8-설정!$B$10) | H8: =IF(A8="","",IF(AND(G8>=0,G8<=설정!$B$19),B8&" D-"&G8,""))
F9: =IF(A9="","",TEXT(A9,"yyyy-mm")) | G9: =IF(A9="","",A9-설정!$B$10) | H9: =IF(A9="","",IF(AND(G9>=0,G9<=설정!$B$19),B9&" D-"&G9,""))
F10: =IF(A10="","",TEXT(A10,"yyyy-mm")) | G10: =IF(A10="","",A10-설정!$B$10) | H10: =IF(A10="","",IF(AND(G10>=0,G10<=설정!$B$19),B10&" D-"&G10,""))
F11: =IF(A11="","",TEXT(A11,"yyyy-mm")) | G11: =IF(A11="","",A11-설정!$B$10) | H11: =IF(A11="","",IF(AND(G11>=0,G11<=설정!$B$19),B11&" D-"&G11,""))
F12: =IF(A12="","",TEXT(A12,"yyyy-mm")) | G12: =IF(A12="","",A12-설정!$B$10) | H12: =IF(A12="","",IF(AND(G12>=0,G12<=설정!$B$19),B12&" D-"&G12,""))
F13: =IF(A13="","",TEXT(A13,"yyyy-mm")) | G13: =IF(A13="","",A13-설정!$B$10) | H13: =IF(A13="","",IF(AND(G13>=0,G13<=설정!$B$19),B13&" D-"&G13,""))
F14: =IF(A14="","",TEXT(A14,"yyyy-mm")) | G14: =IF(A14="","",A14-설정!$B$10) | H14: =IF(A14="","",IF(AND(G14>=0,G14<=설정!$B$19),B14&" D-"&G14,""))
F15: =IF(A15="","",TEXT(A15,"yyyy-mm")) | G15: =IF(A15="","",A15-설정!$B$10) | H15: =IF(A15="","",IF(AND(G15>=0,G15<=설정!$B$19),B15&" D-"&G15,""))
... F63: =IF(A63="","",TEXT(A63,"yyyy-mm")) | G63: =IF(A63="","",A63-설정!$B$10) | H63: =IF(A63="","",IF(AND(G63>=0,G63<=설정!$B$19),B63&" D-"&G63,""))

Sheet 예산
A1: 📋 예산 대비 실적
A2: 고정비·변동비는 월 예산, 비정기비는 연 예산(경과 월수만큼 안분)과 비교합니다. 실적은 대시보드 '보기' 구성원 기준.
A3: 카테고리 | B3: 대분류 | C3: 기준 | D3: 예산 | E3: 경과 예산 | F3: 실적 | G3: 집행률 | H3: 잔여 | I3: 상태 | J3: 실적-본인 | K3: 실적-배우자 | L3: 실적-공동 | M3: (알림용)
A4: 주거관리비 | B4: =IF(A4="","",IFERROR(INDEX(카테고리!$B$2:$B$200,MATCH(A4,카테고리!$A$2:$A$200,0)),"?")) -> 고정비 | C4: 월 | D4: 320000 | E4: =IF(A4="","",IF(C4="연",D4*설정!$B$9/12,D4)) -> 320000 | F4: =IF($A4="","",IF($C4="연",SUMIFS(거래내역!$D$2:$D$5000,거래내역!$E$2:$E$5000,$A4,거래내역!$L$2:$L$5000,">="&설정!$B$8,거래내역!$L$2:$L$5000,"<="&설정!$B$7,거래내역!$H$2:$H$5000,설정!$B$5),SUMIFS(거래내역!$D$2:$D$5000,거래내역!$E$2:$E$5000,$A4,거래내역!$B$2:$B$5000,설정!$B$3,거래내역!$H$2:$H$5000,설정!$B$5))) -> 0 | G4: =IF(OR(A4="",N(E4)=0),"",F4/E4) -> 0 | H4: =IF(A4="","",E4-F4) -> 320000 | I4: =IF(OR(A4="",N(E4)=0),"",IF(G4>1,"🔴 초과",IF(AND(G4>=0.9,B4<>"고정비"),"⚠ 주의","✅ 양호"))) -> ✅ 양호 | J4: =IF($A4="","",IF($C4="연",SUMIFS(거래내역!$D$2:$D$5000,거래내역!$E$2:$E$5000,$A4,거래내역!$L$2:$L$5000,">="&설정!$B$8,거래내역!$L$2:$L$5000,"<="&설정!$B$7,거래내역!$H$2:$H$5000,"본인"),SUMIFS(거래내역!$D$2:$D$5000,거래내역!$E$2:$E$5000,$A4,거래내역!$B$2:$B$5000,설정!$B$3,거래내역!$H$2:$H$5000,"본인"))) -> 0 | K4: =IF($A4="","",IF($C4="연",SUMIFS(거래내역!$D$2:$D$5000,거래내역!$E$2:$E$5000,$A4,거래내역!$L$2:$L$5000,">="&설정!$B$8,거래내역!$L$2:$L$5000,"<="&설정!$B$7,거래내역!$H$2:$H$5000,"배우자"),SUMIFS(거래내역!$D$2:$D$5000,거래내역!$E$2:$E$5000,$A4,거래내역!$B$2:$B$5000,설정!$B$3,거래내역!$H$2:$H$5000,"배우자"))) -> 0 | L4: =IF($A4="","",IF($C4="연",SUMIFS(거래내역!$D$2:$D$5000,거래내역!$E$2:$E$5000,$A4,거래내역!$L$2:$L$5000,">="&설정!$B$8,거래내역!$L$2:$L$5000,"<="&설정!$B$7,거래내역!$H$2:$H$5000,"공동"),SUMIFS(거래내역!$D$2:$D$5000,거래내역!$E$2:$E$5000,$A4,거래내역!$B$2:$B$5000,설정!$B$3,거래내역!$H$2:$H$5000,"공동"))) -> 0 | M4: =IF(ISNUMBER(SEARCH("초과",I4)),A4&" "&TEXT(G4,"0%"),"")
A5: 대출이자 | B5: =IF(A5="","",IFERROR(INDEX(카테고리!$B$2:$B$200,MATCH(A5,카테고리!$A$2:$A$200,0)),"?")) -> 고정비 | C5: 월 | D5: 1100000 | E5: =IF(A5="","",IF(C5="연",D5*설정!$B$9/12,D5)) -> 1100000 | F5: =IF($A5="","",IF($C5="연",SUMIFS(거래내역!$D$2:$D$5000,거래내역!$E$2:$E$5000,$A5,거래내역!$L$2:$L$5000,">="&설정!$B$8,거래내역!$L$2:$L$5000,"<="&설정!$B$7,거래내역!$H$2:$H$5000,설정!$B$5),SUMIFS(거래내역!$D$2:$D$5000,거래내역!$E$2:$E$5000,$A5,거래내역!$B$2:$B$5000,설정!$B$3,거래내역!$H$2:$H$5000,설정!$B$5))) -> 0 | G5: =IF(OR(A5="",N(E5)=0),"",F5/E5) -> 0 | H5: =IF(A5="","",E5-F5) -> 1100000 | I5: =IF(OR(A5="",N(E5)=0),"",IF(G5>1,"🔴 초과",IF(AND(G5>=0.9,B5<>"고정비"),"⚠ 주의","✅ 양호"))) -> ✅ 양호 | J5: =IF($A5="","",IF($C5="연",SUMIFS(거래내역!$D$2:$D$5000,거래내역!$E$2:$E$5000,$A5,거래내역!$L$2:$L$5000,">="&설정!$B$8,거래내역!$L$2:$L$5000,"<="&설정!$B$7,거래내역!$H$2:$H$5000,"본인"),SUMIFS(거래내역!$D$2:$D$5000,거래내역!$E$2:$E$5000,$A5,거래내역!$B$2:$B$5000,설정!$B$3,거래내역!$H$2:$H$5000,"본인"))) -> 0 | K5: =IF($A5="","",IF($C5="연",SUMIFS(거래내역!$D$2:$D$5000,거래내역!$E$2:$E$5000,$A5,거래내역!$L$2:$L$5000,">="&설정!$B$8,거래내역!$L$2:$L$5000,"<="&설정!$B$7,거래내역!$H$2:$H$5000,"배우자"),SUMIFS(거래내역!$D$2:$D$5000,거래내역!$E$2:$E$5000,$A5,거래내역!$B$2:$B$5000,설정!$B$3,거래내역!$H$2:$H$5000,"배우자"))) -> 0 | L5: =IF($A5="","",IF($C5="연",SUMIFS(거래내역!$D$2:$D$5000,거래내역!$E$2:$E$5000,$A5,거래내역!$L$2:$L$5000,">="&설정!$B$8,거래내역!$L$2:$L$5000,"<="&설정!$B$7,거래내역!$H$2:$H$5000,"공동"),SUMIFS(거래내역!$D$2:$D$5000,거래내역!$E$2:$E$5000,$A5,거래내역!$B$2:$B$5000,설정!$B$3,거래내역!$H$2:$H$5000,"공동"))) -> 0 | M5: =IF(ISNUMBER(SEARCH("초과",I5)),A5&" "&TEXT(G5,"0%"),"")
A6: 보험료 | B6: =IF(A6="","",IFERROR(INDEX(카테고리!$B$2:$B$200,MATCH(A6,카테고리!$A$2:$A$200,0)),"?")) -> 고정비 | C6: 월 | D6: 400000 | E6: =IF(A6="","",IF(C6="연",D6*설정!$B$9/12,D6)) -> 400000 | F6: =IF($A6="","",IF($C6="연",SUMIFS(거래내역!$D$2:$D$5000,거래내역!$E$2:$E$5000,$A6,거래내역!$L$2:$L$5000,">="&설정!$B$8,거래내역!$L$2:$L$5000,"<="&설정!$B$7,거래내역!$H$2:$H$5000,설정!$B$5),SUMIFS(거래내역!$D$2:$D$5000,거래내역!$E$2:$E$5000,$A6,거래내역!$B$2:$B$5000,설정!$B$3,거래내역!$H$2:$H$5000,설정!$B$5))) -> 0 | G6: =IF(OR(A6="",N(E6)=0),"",F6/E6) -> 0 | H6: =IF(A6="","",E6-F6) -> 400000 | I6: =IF(OR(A6="",N(E6)=0),"",IF(G6>1,"🔴 초과",IF(AND(G6>=0.9,B6<>"고정비"),"⚠ 주의","✅ 양호"))) -> ✅ 양호 | J6: =IF($A6="","",IF($C6="연",SUMIFS(거래내역!$D$2:$D$5000,거래내역!$E$2:$E$5000,$A6,거래내역!$L$2:$L$5000,">="&설정!$B$8,거래내역!$L$2:$L$5000,"<="&설정!$B$7,거래내역!$H$2:$H$5000,"본인"),SUMIFS(거래내역!$D$2:$D$5000,거래내역!$E$2:$E$5000,$A6,거래내역!$B$2:$B$5000,설정!$B$3,거래내역!$H$2:$H$5000,"본인"))) -> 0 | K6: =IF($A6="","",IF($C6="연",SUMIFS(거래내역!$D$2:$D$5000,거래내역!$E$2:$E$5000,$A6,거래내역!$L$2:$L$5000,">="&설정!$B$8,거래내역!$L$2:$L$5000,"<="&설정!$B$7,거래내역!$H$2:$H$5000,"배우자"),SUMIFS(거래내역!$D$2:$D$5000,거래내역!$E$2:$E$5000,$A6,거래내역!$B$2:$B$5000,설정!$B$3,거래내역!$H$2:$H$5000,"배우자"))) -> 0 | L6: =IF($A6="","",IF($C6="연",SUMIFS(거래내역!$D$2:$D$5000,거래내역!$E$2:$E$5000,$A6,거래내역!$L$2:$L$5000,">="&설정!$B$8,거래내역!$L$2:$L$5000,"<="&설정!$B$7,거래내역!$H$2:$H$5000,"공동"),SUMIFS(거래내역!$D$2:$D$5000,거래내역!$E$2:$E$5000,$A6,거래내역!$B$2:$B$5000,설정!$B$3,거래내역!$H$2:$H$5000,"공동"))) -> 0 | M6: =IF(ISNUMBER(SEARCH("초과",I6)),A6&" "&TEXT(G6,"0%"),"")
A7: 통신비 | B7: =IF(A7="","",IFERROR(INDEX(카테고리!$B$2:$B$200,MATCH(A7,카테고리!$A$2:$A$200,0)),"?")) -> 고정비 | C7: 월 | D7: 160000 | E7: =IF(A7="","",IF(C7="연",D7*설정!$B$9/12,D7)) -> 160000 | F7: =IF($A7="","",IF($C7="연",SUMIFS(거래내역!$D$2:$D$5000,거래내역!$E$2:$E$5000,$A7,거래내역!$L$2:$L$5000,">="&설정!$B$8,거래내역!$L$2:$L$5000,"<="&설정!$B$7,거래내역!$H$2:$H$5000,설정!$B$5),SUMIFS(거래내역!$D$2:$D$5000,거래내역!$E$2:$E$5000,$A7,거래내역!$B$2:$B$5000,설정!$B$3,거래내역!$H$2:$H$5000,설정!$B$5))) -> 0 | G7: =IF(OR(A7="",N(E7)=0),"",F7/E7) -> 0 | H7: =IF(A7="","",E7-F7) -> 160000 | I7: =IF(OR(A7="",N(E7)=0),"",IF(G7>1,"🔴 초과",IF(AND(G7>=0.9,B7<>"고정비"),"⚠ 주의","✅ 양호"))) -> ✅ 양호 | J7: =IF($A7="","",IF($C7="연",SUMIFS(거래내역!$D$2:$D$5000,거래내역!$E$2:$E$5000,$A7,거래내역!$L$2:$L$5000,">="&설정!$B$8,거래내역!$L$2:$L$5000,"<="&설정!$B$7,거래내역!$H$2:$H$5000,"본인"),SUMIFS(거래내역!$D$2:$D$5000,거래내역!$E$2:$E$5000,$A7,거래내역!$B$2:$B$5000,설정!$B$3,거래내역!$H$2:$H$5000,"본인"))) -> 0 | K7: =IF($A7="","",IF($C7="연",SUMIFS(거래내역!$D$2:$D$5000,거래내역!$E$2:$E$5000,$A7,거래내역!$L$2:$L$5000,">="&설정!$B$8,거래내역!$L$2:$L$5000,"<="&설정!$B$7,거래내역!$H$2:$H$5000,"배우자"),SUMIFS(거래내역!$D$2:$D$5000,거래내역!$E$2:$E$5000,$A7,거래내역!$B$2:$B$5000,설정!$B$3,거래내역!$H$2:$H$5000,"배우자"))) -> 0 | L7: =IF($A7="","",IF($C7="연",SUMIFS(거래내역!$D$2:$D$5000,거래내역!$E$2:$E$5000,$A7,거래내역!$L$2:$L$5000,">="&설정!$B$8,거래내역!$L$2:$L$5000,"<="&설정!$B$7,거래내역!$H$2:$H$5000,"공동"),SUMIFS(거래내역!$D$2:$D$5000,거래내역!$E$2:$E$5000,$A7,거래내역!$B$2:$B$5000,설정!$B$3,거래내역!$H$2:$H$5000,"공동"))) -> 0 | M7: =IF(ISNUMBER(SEARCH("초과",I7)),A7&" "&TEXT(G7,"0%"),"")
A8: 교육비 | B8: =IF(A8="","",IFERROR(INDEX(카테고리!$B$2:$B$200,MATCH(A8,카테고리!$A$2:$A$200,0)),"?")) -> 고정비 | C8: 월 | D8: 550000 | E8: =IF(A8="","",IF(C8="연",D8*설정!$B$9/12,D8)) -> 550000 | F8: =IF($A8="","",IF($C8="연",SUMIFS(거래내역!$D$2:$D$5000,거래내역!$E$2:$E$5000,$A8,거래내역!$L$2:$L$5000,">="&설정!$B$8,거래내역!$L$2:$L$5000,"<="&설정!$B$7,거래내역!$H$2:$H$5000,설정!$B$5),SUMIFS(거래내역!$D$2:$D$5000,거래내역!$E$2:$E$5000,$A8,거래내역!$B$2:$B$5000,설정!$B$3,거래내역!$H$2:$H$5000,설정!$B$5))) -> 0 | G8: =IF(OR(A8="",N(E8)=0),"",F8/E8) -> 0 | H8: =IF(A8="","",E8-F8) -> 550000 | I8: =IF(OR(A8="",N(E8)=0),"",IF(G8>1,"🔴 초과",IF(AND(G8>=0.9,B8<>"고정비"),"⚠ 주의","✅ 양호"))) -> ✅ 양호 | J8: =IF($A8="","",IF($C8="연",SUMIFS(거래내역!$D$2:$D$5000,거래내역!$E$2:$E$5000,$A8,거래내역!$L$2:$L$5000,">="&설정!$B$8,거래내역!$L$2:$L$5000,"<="&설정!$B$7,거래내역!$H$2:$H$5000,"본인"),SUMIFS(거래내역!$D$2:$D$5000,거래내역!$E$2:$E$5000,$A8,거래내역!$B$2:$B$5000,설정!$B$3,거래내역!$H$2:$H$5000,"본인"))) -> 0 | K8: =IF($A8="","",IF($C8="연",SUMIFS(거래내역!$D$2:$D$5000,거래내역!$E$2:$E$5000,$A8,거래내역!$L$2:$L$5000,">="&설정!$B$8,거래내역!$L$2:$L$5000,"<="&설정!$B$7,거래내역!$H$2:$H$5000,"배우자"),SUMIFS(거래내역!$D$2:$D$5000,거래내역!$E$2:$E$5000,$A8,거래내역!$B$2:$B$5000,설정!$B$3,거래내역!$H$2:$H$5000,"배우자"))) -> 0 | L8: =IF($A8="","",IF($C8="연",SUMIFS(거래내역!$D$2:$D$5000,거래내역!$E$2:$E$5000,$A8,거래내역!$L$2:$L$5000,">="&설정!$B$8,거래내역!$L$2:$L$5000,"<="&설정!$B$7,거래내역!$H$2:$H$5000,"공동"),SUMIFS(거래내역!$D$2:$D$5000,거래내역!$E$2:$E$5000,$A8,거래내역!$B$2:$B$5000,설정!$B$3,거래내역!$H$2:$H$5000,"공동"))) -> 0 | M8: =IF(ISNUMBER(SEARCH("초과",I8)),A8&" "&TEXT(G8,"0%"),"")
A9: 구독료 | B9: =IF(A9="","",IFERROR(INDEX(카테고리!$B$2:$B$200,MATCH(A9,카테고리!$A$2:$A$200,0)),"?")) -> 고정비 | C9: 월 | D9: 50000 | E9: =IF(A9="","",IF(C9="연",D9*설정!$B$9/12,D9)) -> 50000 | F9: =IF($A9="","",IF($C9="연",SUMIFS(거래내역!$D$2:$D$5000,거래내역!$E$2:$E$5000,$A9,거래내역!$L$2:$L$5000,">="&설정!$B$8,거래내역!$L$2:$L$5000,"<="&설정!$B$7,거래내역!$H$2:$H$5000,설정!$B$5),SUMIFS(거래내역!$D$2:$D$5000,거래내역!$E$2:$E$5000,$A9,거래내역!$B$2:$B$5000,설정!$B$3,거래내역!$H$2:$H$5000,설정!$B$5))) -> 0 | G9: =IF(OR(A9="",N(E9)=0),"",F9/E9) -> 0 | H9: =IF(A9="","",E9-F9) -> 50000 | I9: =IF(OR(A9="",N(E9)=0),"",IF(G9>1,"🔴 초과",IF(AND(G9>=0.9,B9<>"고정비"),"⚠ 주의","✅ 양호"))) -> ✅ 양호 | J9: =IF($A9="","",IF($C9="연",SUMIFS(거래내역!$D$2:$D$5000,거래내역!$E$2:$E$5000,$A9,거래내역!$L$2:$L$5000,">="&설정!$B$8,거래내역!$L$2:$L$5000,"<="&설정!$B$7,거래내역!$H$2:$H$5000,"본인"),SUMIFS(거래내역!$D$2:$D$5000,거래내역!$E$2:$E$5000,$A9,거래내역!$B$2:$B$5000,설정!$B$3,거래내역!$H$2:$H$5000,"본인"))) -> 0 | K9: =IF($A9="","",IF($C9="연",SUMIFS(거래내역!$D$2:$D$5000,거래내역!$E$2:$E$5000,$A9,거래내역!$L$2:$L$5000,">="&설정!$B$8,거래내역!$L$2:$L$5000,"<="&설정!$B$7,거래내역!$H$2:$H$5000,"배우자"),SUMIFS(거래내역!$D$2:$D$5000,거래내역!$E$2:$E$5000,$A9,거래내역!$B$2:$B$5000,설정!$B$3,거래내역!$H$2:$H$5000,"배우자"))) -> 0 | L9: =IF($A9="","",IF($C9="연",SUMIFS(거래내역!$D$2:$D$5000,거래내역!$E$2:$E$5000,$A9,거래내역!$L$2:$L$5000,">="&설정!$B$8,거래내역!$L$2:$L$5000,"<="&설정!$B$7,거래내역!$H$2:$H$5000,"공동"),SUMIFS(거래내역!$D$2:$D$5000,거래내역!$E$2:$E$5000,$A9,거래내역!$B$2:$B$5000,설정!$B$3,거래내역!$H$2:$H$5000,"공동"))) -> 0 | M9: =IF(ISNUMBER(SEARCH("초과",I9)),A9&" "&TEXT(G9,"0%"),"")
A10: 식비 | B10: =IF(A10="","",IFERROR(INDEX(카테고리!$B$2:$B$200,MATCH(A10,카테고리!$A$2:$A$200,0)),"?")) -> 변동비 | C10: 월 | D10: 900000 | E10: =IF(A10="","",IF(C10="연",D10*설정!$B$9/12,D10)) -> 900000 | F10: =IF($A10="","",IF($C10="연",SUMIFS(거래내역!$D$2:$D$5000,거래내역!$E$2:$E$5000,$A10,거래내역!$L$2:$L$5000,">="&설정!$B$8,거래내역!$L$2:$L$5000,"<="&설정!$B$7,거래내역!$H$2:$H$5000,설정!$B$5),SUMIFS(거래내역!$D$2:$D$5000,거래내역!$E$2:$E$5000,$A10,거래내역!$B$2:$B$5000,설정!$B$3,거래내역!$H$2:$H$5000,설정!$B$5))) -> 0 | G10: =IF(OR(A10="",N(E10)=0),"",F10/E10) -> 0 | H10: =IF(A10="","",E10-F10) -> 900000 | I10: =IF(OR(A10="",N(E10)=0),"",IF(G10>1,"🔴 초과",IF(AND(G10>=0.9,B10<>"고정비"),"⚠ 주의","✅ 양호"))) -> ✅ 양호 | J10: =IF($A10="","",IF($C10="연",SUMIFS(거래내역!$D$2:$D$5000,거래내역!$E$2:$E$5000,$A10,거래내역!$L$2:$L$5000,">="&설정!$B$8,거래내역!$L$2:$L$5000,"<="&설정!$B$7,거래내역!$H$2:$H$5000,"본인"),SUMIFS(거래내역!$D$2:$D$5000,거래내역!$E$2:$E$5000,$A10,거래내역!$B$2:$B$5000,설정!$B$3,거래내역!$H$2:$H$5000,"본인"))) -> 0 | K10: =IF($A10="","",IF($C10="연",SUMIFS(거래내역!$D$2:$D$5000,거래내역!$E$2:$E$5000,$A10,거래내역!$L$2:$L$5000,">="&설정!$B$8,거래내역!$L$2:$L$5000,"<="&설정!$B$7,거래내역!$H$2:$H$5000,"배우자"),SUMIFS(거래내역!$D$2:$D$5000,거래내역!$E$2:$E$5000,$A10,거래내역!$B$2:$B$5000,설정!$B$3,거래내역!$H$2:$H$5000,"배우자"))) -> 0 | L10: =IF($A10="","",IF($C10="연",SUMIFS(거래내역!$D$2:$D$5000,거래내역!$E$2:$E$5000,$A10,거래내역!$L$2:$L$5000,">="&설정!$B$8,거래내역!$L$2:$L$5000,"<="&설정!$B$7,거래내역!$H$2:$H$5000,"공동"),SUMIFS(거래내역!$D$2:$D$5000,거래내역!$E$2:$E$5000,$A10,거래내역!$B$2:$B$5000,설정!$B$3,거래내역!$H$2:$H$5000,"공동"))) -> 0 | M10: =IF(ISNUMBER(SEARCH("초과",I10)),A10&" "&TEXT(G10,"0%"),"")
A11: 외식 | B11: =IF(A11="","",IFERROR(INDEX(카테고리!$B$2:$B$200,MATCH(A11,카테고리!$A$2:$A$200,0)),"?")) -> 변동비 | C11: 월 | D11: 400000 | E11: =IF(A11="","",IF(C11="연",D11*설정!$B$9/12,D11)) -> 400000 | F11: =IF($A11="","",IF($C11="연",SUMIFS(거래내역!$D$2:$D$5000,거래내역!$E$2:$E$5000,$A11,거래내역!$L$2:$L$5000,">="&설정!$B$8,거래내역!$L$2:$L$5000,"<="&설정!$B$7,거래내역!$H$2:$H$5000,설정!$B$5),SUMIFS(거래내역!$D$2:$D$5000,거래내역!$E$2:$E$5000,$A11,거래내역!$B$2:$B$5000,설정!$B$3,거래내역!$H$2:$H$5000,설정!$B$5))) -> 0 | G11: =IF(OR(A11="",N(E11)=0),"",F11/E11) -> 0 | H11: =IF(A11="","",E11-F11) -> 400000 | I11: =IF(OR(A11="",N(E11)=0),"",IF(G11>1,"🔴 초과",IF(AND(G11>=0.9,B11<>"고정비"),"⚠ 주의","✅ 양호"))) -> ✅ 양호 | J11: =IF($A11="","",IF($C11="연",SUMIFS(거래내역!$D$2:$D$5000,거래내역!$E$2:$E$5000,$A11,거래내역!$L$2:$L$5000,">="&설정!$B$8,거래내역!$L$2:$L$5000,"<="&설정!$B$7,거래내역!$H$2:$H$5000,"본인"),SUMIFS(거래내역!$D$2:$D$5000,거래내역!$E$2:$E$5000,$A11,거래내역!$B$2:$B$5000,설정!$B$3,거래내역!$H$2:$H$5000,"본인"))) -> 0 | K11: =IF($A11="","",IF($C11="연",SUMIFS(거래내역!$D$2:$D$5000,거래내역!$E$2:$E$5000,$A11,거래내역!$L$2:$L$5000,">="&설정!$B$8,거래내역!$L$2:$L$5000,"<="&설정!$B$7,거래내역!$H$2:$H$5000,"배우자"),SUMIFS(거래내역!$D$2:$D$5000,거래내역!$E$2:$E$5000,$A11,거래내역!$B$2:$B$5000,설정!$B$3,거래내역!$H$2:$H$5000,"배우자"))) -> 0 | L11: =IF($A11="","",IF($C11="연",SUMIFS(거래내역!$D$2:$D$5000,거래내역!$E$2:$E$5000,$A11,거래내역!$L$2:$L$5000,">="&설정!$B$8,거래내역!$L$2:$L$5000,"<="&설정!$B$7,거래내역!$H$2:$H$5000,"공동"),SUMIFS(거래내역!$D$2:$D$5000,거래내역!$E$2:$E$5000,$A11,거래내역!$B$2:$B$5000,설정!$B$3,거래내역!$H$2:$H$5000,"공동"))) -> 0 | M11: =IF(ISNUMBER(SEARCH("초과",I11)),A11&" "&TEXT(G11,"0%"),"")
A12: 생활용품 | B12: =IF(A12="","",IFERROR(INDEX(카테고리!$B$2:$B$200,MATCH(A12,카테고리!$A$2:$A$200,0)),"?")) -> 변동비 | C12: 월 | D12: 250000 | E12: =IF(A12="","",IF(C12="연",D12*설정!$B$9/12,D12)) -> 250000 | F12: =IF($A12="","",IF($C12="연",SUMIFS(거래내역!$D$2:$D$5000,거래내역!$E$2:$E$5000,$A12,거래내역!$L$2:$L$5000,">="&설정!$B$8,거래내역!$L$2:$L$5000,"<="&설정!$B$7,거래내역!$H$2:$H$5000,설정!$B$5),SUMIFS(거래내역!$D$2:$D$5000,거래내역!$E$2:$E$5000,$A12,거래내역!$B$2:$B$5000,설정!$B$3,거래내역!$H$2:$H$5000,설정!$B$5))) -> 0 | G12: =IF(OR(A12="",N(E12)=0),"",F12/E12) -> 0 | H12: =IF(A12="","",E12-F12) -> 250000 | I12: =IF(OR(A12="",N(E12)=0),"",IF(G12>1,"🔴 초과",IF(AND(G12>=0.9,B12<>"고정비"),"⚠ 주의","✅ 양호"))) -> ✅ 양호 | J12: =IF($A12="","",IF($C12="연",SUMIFS(거래내역!$D$2:$D$5000,거래내역!$E$2:$E$5000,$A12,거래내역!$L$2:$L$5000,">="&설정!$B$8,거래내역!$L$2:$L$5000,"<="&설정!$B$7,거래내역!$H$2:$H$5000,"본인"),SUMIFS(거래내역!$D$2:$D$5000,거래내역!$E$2:$E$5000,$A12,거래내역!$B$2:$B$5000,설정!$B$3,거래내역!$H$2:$H$5000,"본인"))) -> 0 | K12: =IF($A12="","",IF($C12="연",SUMIFS(거래내역!$D$2:$D$5000,거래내역!$E$2:$E$5000,$A12,거래내역!$L$2:$L$5000,">="&설정!$B$8,거래내역!$L$2:$L$5000,"<="&설정!$B$7,거래내역!$H$2:$H$5000,"배우자"),SUMIFS(거래내역!$D$2:$D$5000,거래내역!$E$2:$E$5000,$A12,거래내역!$B$2:$B$5000,설정!$B$3,거래내역!$H$2:$H$5000,"배우자"))) -> 0 | L12: =IF($A12="","",IF($C12="연",SUMIFS(거래내역!$D$2:$D$5000,거래내역!$E$2:$E$5000,$A12,거래내역!$L$2:$L$5000,">="&설정!$B$8,거래내역!$L$2:$L$5000,"<="&설정!$B$7,거래내역!$H$2:$H$5000,"공동"),SUMIFS(거래내역!$D$2:$D$5000,거래내역!$E$2:$E$5000,$A12,거래내역!$B$2:$B$5000,설정!$B$3,거래내역!$H$2:$H$5000,"공동"))) -> 0 | M12: =IF(ISNUMBER(SEARCH("초과",I12)),A12&" "&TEXT(G12,"0%"),"")
A13: 교통 | B13: =IF(A13="","",IFERROR(INDEX(카테고리!$B$2:$B$200,MATCH(A13,카테고리!$A$2:$A$200,0)),"?")) -> 변동비 | C13: 월 | D13: 330000 | E13: =IF(A13="","",IF(C13="연",D13*설정!$B$9/12,D13)) -> 330000 | F13: =IF($A13="","",IF($C13="연",SUMIFS(거래내역!$D$2:$D$5000,거래내역!$E$2:$E$5000,$A13,거래내역!$L$2:$L$5000,">="&설정!$B$8,거래내역!$L$2:$L$5000,"<="&설정!$B$7,거래내역!$H$2:$H$5000,설정!$B$5),SUMIFS(거래내역!$D$2:$D$5000,거래내역!$E$2:$E$5000,$A13,거래내역!$B$2:$B$5000,설정!$B$3,거래내역!$H$2:$H$5000,설정!$B$5))) -> 0 | G13: =IF(OR(A13="",N(E13)=0),"",F13/E13) -> 0 | H13: =IF(A13="","",E13-F13) -> 330000 | I13: =IF(OR(A13="",N(E13)=0),"",IF(G13>1,"🔴 초과",IF(AND(G13>=0.9,B13<>"고정비"),"⚠ 주의","✅ 양호"))) -> ✅ 양호 | J13: =IF($A13="","",IF($C13="연",SUMIFS(거래내역!$D$2:$D$5000,거래내역!$E$2:$E$5000,$A13,거래내역!$L$2:$L$5000,">="&설정!$B$8,거래내역!$L$2:$L$5000,"<="&설정!$B$7,거래내역!$H$2:$H$5000,"본인"),SUMIFS(거래내역!$D$2:$D$5000,거래내역!$E$2:$E$5000,$A13,거래내역!$B$2:$B$5000,설정!$B$3,거래내역!$H$2:$H$5000,"본인"))) -> 0 | K13: =IF($A13="","",IF($C13="연",SUMIFS(거래내역!$D$2:$D$5000,거래내역!$E$2:$E$5000,$A13,거래내역!$L$2:$L$5000,">="&설정!$B$8,거래내역!$L$2:$L$5000,"<="&설정!$B$7,거래내역!$H$2:$H$5000,"배우자"),SUMIFS(거래내역!$D$2:$D$5000,거래내역!$E$2:$E$5000,$A13,거래내역!$B$2:$B$5000,설정!$B$3,거래내역!$H$2:$H$5000,"배우자"))) -> 0 | L13: =IF($A13="","",IF($C13="연",SUMIFS(거래내역!$D$2:$D$5000,거래내역!$E$2:$E$5000,$A13,거래내역!$L$2:$L$5000,">="&설정!$B$8,거래내역!$L$2:$L$5000,"<="&설정!$B$7,거래내역!$H$2:$H$5000,"공동"),SUMIFS(거래내역!$D$2:$D$5000,거래내역!$E$2:$E$5000,$A13,거래내역!$B$2:$B$5000,설정!$B$3,거래내역!$H$2:$H$5000,"공동"))) -> 0 | M13: =IF(ISNUMBER(SEARCH("초과",I13)),A13&" "&TEXT(G13,"0%"),"")
A14: 쇼핑 | B14: =IF(A14="","",IFERROR(INDEX(카테고리!$B$2:$B$200,MATCH(A14,카테고리!$A$2:$A$200,0)),"?")) -> 변동비 | C14: 월 | D14: 300000 | E14: =IF(A14="","",IF(C14="연",D14*설정!$B$9/12,D14)) -> 300000 | F14: =IF($A14="","",IF($C14="연",SUMIFS(거래내역!$D$2:$D$5000,거래내역!$E$2:$E$5000,$A14,거래내역!$L$2:$L$5000,">="&설정!$B$8,거래내역!$L$2:$L$5000,"<="&설정!$B$7,거래내역!$H$2:$H$5000,설정!$B$5),SUMIFS(거래내역!$D$2:$D$5000,거래내역!$E$2:$E$5000,$A14,거래내역!$B$2:$B$5000,설정!$B$3,거래내역!$H$2:$H$5000,설정!$B$5))) -> 0 | G14: =IF(OR(A14="",N(E14)=0),"",F14/E14) -> 0 | H14: =IF(A14="","",E14-F14) -> 300000 | I14: =IF(OR(A14="",N(E14)=0),"",IF(G14>1,"🔴 초과",IF(AND(G14>=0.9,B14<>"고정비"),"⚠ 주의","✅ 양호"))) -> ✅ 양호 | J14: =IF($A14="","",IF($C14="연",SUMIFS(거래내역!$D$2:$D$5000,거래내역!$E$2:$E$5000,$A14,거래내역!$L$2:$L$5000,">="&설정!$B$8,거래내역!$L$2:$L$5000,"<="&설정!$B$7,거래내역!$H$2:$H$5000,"본인"),SUMIFS(거래내역!$D$2:$D$5000,거래내역!$E$2:$E$5000,$A14,거래내역!$B$2:$B$5000,설정!$B$3,거래내역!$H$2:$H$5000,"본인"))) -> 0 | K14: =IF($A14="","",IF($C14="연",SUMIFS(거래내역!$D$2:$D$5000,거래내역!$E$2:$E$5000,$A14,거래내역!$L$2:$L$5000,">="&설정!$B$8,거래내역!$L$2:$L$5000,"<="&설정!$B$7,거래내역!$H$2:$H$5000,"배우자"),SUMIFS(거래내역!$D$2:$D$5000,거래내역!$E$2:$E$5000,$A14,거래내역!$B$2:$B$5000,설정!$B$3,거래내역!$H$2:$H$5000,"배우자"))) -> 0 | L14: =IF($A14="","",IF($C14="연",SUMIFS(거래내역!$D$2:$D$5000,거래내역!$E$2:$E$5000,$A14,거래내역!$L$2:$L$5000,">="&설정!$B$8,거래내역!$L$2:$L$5000,"<="&설정!$B$7,거래내역!$H$2:$H$5000,"공동"),SUMIFS(거래내역!$D$2:$D$5000,거래내역!$E$2:$E$5000,$A14,거래내역!$B$2:$B$5000,설정!$B$3,거래내역!$H$2:$H$5000,"공동"))) -> 0 | M14: =IF(ISNUMBER(SEARCH("초과",I14)),A14&" "&TEXT(G14,"0%"),"")
A15: 의료 | B15: =IF(A15="","",IFERROR(INDEX(카테고리!$B$2:$B$200,MATCH(A15,카테고리!$A$2:$A$200,0)),"?")) -> 변동비 | C15: 월 | D15: 120000 | E15: =IF(A15="","",IF(C15="연",D15*설정!$B$9/12,D15)) -> 120000 | F15: =IF($A15="","",IF($C15="연",SUMIFS(거래내역!$D$2:$D$5000,거래내역!$E$2:$E$5000,$A15,거래내역!$L$2:$L$5000,">="&설정!$B$8,거래내역!$L$2:$L$5000,"<="&설정!$B$7,거래내역!$H$2:$H$5000,설정!$B$5),SUMIFS(거래내역!$D$2:$D$5000,거래내역!$E$2:$E$5000,$A15,거래내역!$B$2:$B$5000,설정!$B$3,거래내역!$H$2:$H$5000,설정!$B$5))) -> 0 | G15: =IF(OR(A15="",N(E15)=0),"",F15/E15) -> 0 | H15: =IF(A15="","",E15-F15) -> 120000 | I15: =IF(OR(A15="",N(E15)=0),"",IF(G15>1,"🔴 초과",IF(AND(G15>=0.9,B15<>"고정비"),"⚠ 주의","✅ 양호"))) -> ✅ 양호 | J15: =IF($A15="","",IF($C15="연",SUMIFS(거래내역!$D$2:$D$5000,거래내역!$E$2:$E$5000,$A15,거래내역!$L$2:$L$5000,">="&설정!$B$8,거래내역!$L$2:$L$5000,"<="&설정!$B$7,거래내역!$H$2:$H$5000,"본인"),SUMIFS(거래내역!$D$2:$D$5000,거래내역!$E$2:$E$5000,$A15,거래내역!$B$2:$B$5000,설정!$B$3,거래내역!$H$2:$H$5000,"본인"))) -> 0 | K15: =IF($A15="","",IF($C15="연",SUMIFS(거래내역!$D$2:$D$5000,거래내역!$E$2:$E$5000,$A15,거래내역!$L$2:$L$5000,">="&설정!$B$8,거래내역!$L$2:$L$5000,"<="&설정!$B$7,거래내역!$H$2:$H$5000,"배우자"),SUMIFS(거래내역!$D$2:$D$5000,거래내역!$E$2:$E$5000,$A15,거래내역!$B$2:$B$5000,설정!$B$3,거래내역!$H$2:$H$5000,"배우자"))) -> 0 | L15: =IF($A15="","",IF($C15="연",SUMIFS(거래내역!$D$2:$D$5000,거래내역!$E$2:$E$5000,$A15,거래내역!$L$2:$L$5000,">="&설정!$B$8,거래내역!$L$2:$L$5000,"<="&설정!$B$7,거래내역!$H$2:$H$5000,"공동"),SUMIFS(거래내역!$D$2:$D$5000,거래내역!$E$2:$E$5000,$A15,거래내역!$B$2:$B$5000,설정!$B$3,거래내역!$H$2:$H$5000,"공동"))) -> 0 | M15: =IF(ISNUMBER(SEARCH("초과",I15)),A15&" "&TEXT(G15,"0%"),"")
... A21: 명절 | B21: =IF(A21="","",IFERROR(INDEX(카테고리!$B$2:$B$200,MATCH(A21,카테고리!$A$2:$A$200,0)),"?")) -> 비정기비 | C21: 연 | D21: 1800000 | E21: =IF(A21="","",IF(C21="연",D21*설정!$B$9/12,D21)) -> 1350000 | F21: =IF($A21="","",IF($C21="연",SUMIFS(거래내역!$D$2:$D$5000,거래내역!$E$2:$E$5000,$A21,거래내역!$L$2:$L$5000,">="&설정!$B$8,거래내역!$L$2:$L$5000,"<="&설정!$B$7,거래내역!$H$2:$H$5000,설정!$B$5),SUMIFS(거래내역!$D$2:$D$5000,거래내역!$E$2:$E$5000,$A21,거래내역!$B$2:$B$5000,설정!$B$3,거래내역!$H$2:$H$5000,설정!$B$5))) -> 0 | G21: =IF(OR(A21="",N(E21)=0),"",F21/E21) -> 0 | H21: =IF(A21="","",E21-F21) -> 1350000 | I21: =IF(OR(A21="",N(E21)=0),"",IF(G21>1,"🔴 초과",IF(AND(G21>=0.9,B21<>"고정비"),"⚠ 주의","✅ 양호"))) -> ✅ 양호 | J21: =IF($A21="","",IF($C21="연",SUMIFS(거래내역!$D$2:$D$5000,거래내역!$E$2:$E$5000,$A21,거래내역!$L$2:$L$5000,">="&설정!$B$8,거래내역!$L$2:$L$5000,"<="&설정!$B$7,거래내역!$H$2:$H$5000,"본인"),SUMIFS(거래내역!$D$2:$D$5000,거래내역!$E$2:$E$5000,$A21,거래내역!$B$2:$B$5000,설정!$B$3,거래내역!$H$2:$H$5000,"본인"))) -> 0 | K21: =IF($A21="","",IF($C21="연",SUMIFS(거래내역!$D$2:$D$5000,거래내역!$E$2:$E$5000,$A21,거래내역!$L$2:$L$5000,">="&설정!$B$8,거래내역!$L$2:$L$5000,"<="&설정!$B$7,거래내역!$H$2:$H$5000,"배우자"),SUMIFS(거래내역!$D$2:$D$5000,거래내역!$E$2:$E$5000,$A21,거래내역!$B$2:$B$5000,설정!$B$3,거래내역!$H$2:$H$5000,"배우자"))) -> 0 | L21: =IF($A21="","",IF($C21="연",SUMIFS(거래내역!$D$2:$D$5000,거래내역!$E$2:$E$5000,$A21,거래내역!$L$2:$L$5000,">="&설정!$B$8,거래내역!$L$2:$L$5000,"<="&설정!$B$7,거래내역!$H$2:$H$5000,"공동"),SUMIFS(거래내역!$D$2:$D$5000,거래내역!$E$2:$E$5000,$A21,거래내역!$B$2:$B$5000,설정!$B$3,거래내역!$H$2:$H$5000,"공동"))) -> 0 | M21: =IF(ISNUMBER(SEARCH("초과",I21)),A21&" "&TEXT(G21,"0%"),"")
B22: =IF(A22="","",IFERROR(INDEX(카테고리!$B$2:$B$200,MATCH(A22,카테고리!$A$2:$A$200,0)),"?")) | E22: =IF(A22="","",IF(C22="연",D22*설정!$B$9/12,D22)) | F22: =IF($A22="","",IF($C22="연",SUMIFS(거래내역!$D$2:$D$5000,거래내역!$E$2:$E$5000,$A22,거래내역!$L$2:$L$5000,">="&설정!$B$8,거래내역!$L$2:$L$5000,"<="&설정!$B$7,거래내역!$H$2:$H$5000,설정!$B$5),SUMIFS(거래내역!$D$2:$D$5000,거래내역!$E$2:$E$5000,$A22,거래내역!$B$2:$B$5000,설정!$B$3,거래내역!$H$2:$H$5000,설정!$B$5))) | G22: =IF(OR(A22="",N(E22)=0),"",F22/E22) | H22: =IF(A22="","",E22-F22) | I22: =IF(OR(A22="",N(E22)=0),"",IF(G22>1,"🔴 초과",IF(AND(G22>=0.9,B22<>"고정비"),"⚠ 주의","✅ 양호"))) | J22: =IF($A22="","",IF($C22="연",SUMIFS(거래내역!$D$2:$D$5000,거래내역!$E$2:$E$5000,$A22,거래내역!$L$2:$L$5000,">="&설정!$B$8,거래내역!$L$2:$L$5000,"<="&설정!$B$7,거래내역!$H$2:$H$5000,"본인"),SUMIFS(거래내역!$D$2:$D$5000,거래내역!$E$2:$E$5000,$A22,거래내역!$B$2:$B$5000,설정!$B$3,거래내역!$H$2:$H$5000,"본인"))) | K22: =IF($A22="","",IF($C22="연",SUMIFS(거래내역!$D$2:$D$5000,거래내역!$E$2:$E$5000,$A22,거래내역!$L$2:$L$5000,">="&설정!$B$8,거래내역!$L$2:$L$5000,"<="&설정!$B$7,거래내역!$H$2:$H$5000,"배우자"),SUMIFS(거래내역!$D$2:$D$5000,거래내역!$E$2:$E$5000,$A22,거래내역!$B$2:$B$5000,설정!$B$3,거래내역!$H$2:$H$5000,"배우자"))) | L22: =IF($A22="","",IF($C22="연",SUMIFS(거래내역!$D$2:$D$5000,거래내역!$E$2:$E$5000,$A22,거래내역!$L$2:$L$5000,">="&설정!$B$8,거래내역!$L$2:$L$5000,"<="&설정!$B$7,거래내역!$H$2:$H$5000,"공동"),SUMIFS(거래내역!$D$2:$D$5000,거래내역!$E$2:$E$5000,$A22,거래내역!$B$2:$B$5000,설정!$B$3,거래내역!$H$2:$H$5000,"공동"))) | M22: =IF(ISNUMBER(SEARCH("초과",I22)),A22&" "&TEXT(G22,"0%"),"")
B23: =IF(A23="","",IFERROR(INDEX(카테고리!$B$2:$B$200,MATCH(A23,카테고리!$A$2:$A$200,0)),"?")) | E23: =IF(A23="","",IF(C23="연",D23*설정!$B$9/12,D23)) | F23: =IF($A23="","",IF($C23="연",SUMIFS(거래내역!$D$2:$D$5000,거래내역!$E$2:$E$5000,$A23,거래내역!$L$2:$L$5000,">="&설정!$B$8,거래내역!$L$2:$L$5000,"<="&설정!$B$7,거래내역!$H$2:$H$5000,설정!$B$5),SUMIFS(거래내역!$D$2:$D$5000,거래내역!$E$2:$E$5000,$A23,거래내역!$B$2:$B$5000,설정!$B$3,거래내역!$H$2:$H$5000,설정!$B$5))) | G23: =IF(OR(A23="",N(E23)=0),"",F23/E23) | H23: =IF(A23="","",E23-F23) | I23: =IF(OR(A23="",N(E23)=0),"",IF(G23>1,"🔴 초과",IF(AND(G23>=0.9,B23<>"고정비"),"⚠ 주의","✅ 양호"))) | J23: =IF($A23="","",IF($C23="연",SUMIFS(거래내역!$D$2:$D$5000,거래내역!$E$2:$E$5000,$A23,거래내역!$L$2:$L$5000,">="&설정!$B$8,거래내역!$L$2:$L$5000,"<="&설정!$B$7,거래내역!$H$2:$H$5000,"본인"),SUMIFS(거래내역!$D$2:$D$5000,거래내역!$E$2:$E$5000,$A23,거래내역!$B$2:$B$5000,설정!$B$3,거래내역!$H$2:$H$5000,"본인"))) | K23: =IF($A23="","",IF($C23="연",SUMIFS(거래내역!$D$2:$D$5000,거래내역!$E$2:$E$5000,$A23,거래내역!$L$2:$L$5000,">="&설정!$B$8,거래내역!$L$2:$L$5000,"<="&설정!$B$7,거래내역!$H$2:$H$5000,"배우자"),SUMIFS(거래내역!$D$2:$D$5000,거래내역!$E$2:$E$5000,$A23,거래내역!$B$2:$B$5000,설정!$B$3,거래내역!$H$2:$H$5000,"배우자"))) | L23: =IF($A23="","",IF($C23="연",SUMIFS(거래내역!$D$2:$D$5000,거래내역!$E$2:$E$5000,$A23,거래내역!$L$2:$L$5000,">="&설정!$B$8,거래내역!$L$2:$L$5000,"<="&설정!$B$7,거래내역!$H$2:$H$5000,"공동"),SUMIFS(거래내역!$D$2:$D$5000,거래내역!$E$2:$E$5000,$A23,거래내역!$B$2:$B$5000,설정!$B$3,거래내역!$H$2:$H$5000,"공동"))) | M23: =IF(ISNUMBER(SEARCH("초과",I23)),A23&" "&TEXT(G23,"0%"),"")
B24: =IF(A24="","",IFERROR(INDEX(카테고리!$B$2:$B$200,MATCH(A24,카테고리!$A$2:$A$200,0)),"?")) | E24: =IF(A24="","",IF(C24="연",D24*설정!$B$9/12,D24)) | F24: =IF($A24="","",IF($C24="연",SUMIFS(거래내역!$D$2:$D$5000,거래내역!$E$2:$E$5000,$A24,거래내역!$L$2:$L$5000,">="&설정!$B$8,거래내역!$L$2:$L$5000,"<="&설정!$B$7,거래내역!$H$2:$H$5000,설정!$B$5),SUMIFS(거래내역!$D$2:$D$5000,거래내역!$E$2:$E$5000,$A24,거래내역!$B$2:$B$5000,설정!$B$3,거래내역!$H$2:$H$5000,설정!$B$5))) | G24: =IF(OR(A24="",N(E24)=0),"",F24/E24) | H24: =IF(A24="","",E24-F24) | I24: =IF(OR(A24="",N(E24)=0),"",IF(G24>1,"🔴 초과",IF(AND(G24>=0.9,B24<>"고정비"),"⚠ 주의","✅ 양호"))) | J24: =IF($A24="","",IF($C24="연",SUMIFS(거래내역!$D$2:$D$5000,거래내역!$E$2:$E$5000,$A24,거래내역!$L$2:$L$5000,">="&설정!$B$8,거래내역!$L$2:$L$5000,"<="&설정!$B$7,거래내역!$H$2:$H$5000,"본인"),SUMIFS(거래내역!$D$2:$D$5000,거래내역!$E$2:$E$5000,$A24,거래내역!$B$2:$B$5000,설정!$B$3,거래내역!$H$2:$H$5000,"본인"))) | K24: =IF($A24="","",IF($C24="연",SUMIFS(거래내역!$D$2:$D$5000,거래내역!$E$2:$E$5000,$A24,거래내역!$L$2:$L$5000,">="&설정!$B$8,거래내역!$L$2:$L$5000,"<="&설정!$B$7,거래내역!$H$2:$H$5000,"배우자"),SUMIFS(거래내역!$D$2:$D$5000,거래내역!$E$2:$E$5000,$A24,거래내역!$B$2:$B$5000,설정!$B$3,거래내역!$H$2:$H$5000,"배우자"))) | L24: =IF($A24="","",IF($C24="연",SUMIFS(거래내역!$D$2:$D$5000,거래내역!$E$2:$E$5000,$A24,거래내역!$L$2:$L$5000,">="&설정!$B$8,거래내역!$L$2:$L$5000,"<="&설정!$B$7,거래내역!$H$2:$H$5000,"공동"),SUMIFS(거래내역!$D$2:$D$5000,거래내역!$E$2:$E$5000,$A24,거래내역!$B$2:$B$5000,설정!$B$3,거래내역!$H$2:$H$5000,"공동"))) | M24: =IF(ISNUMBER(SEARCH("초과",I24)),A24&" "&TEXT(G24,"0%"),"")
B25: =IF(A25="","",IFERROR(INDEX(카테고리!$B$2:$B$200,MATCH(A25,카테고리!$A$2:$A$200,0)),"?")) | E25: =IF(A25="","",IF(C25="연",D25*설정!$B$9/12,D25)) | F25: =IF($A25="","",IF($C25="연",SUMIFS(거래내역!$D$2:$D$5000,거래내역!$E$2:$E$5000,$A25,거래내역!$L$2:$L$5000,">="&설정!$B$8,거래내역!$L$2:$L$5000,"<="&설정!$B$7,거래내역!$H$2:$H$5000,설정!$B$5),SUMIFS(거래내역!$D$2:$D$5000,거래내역!$E$2:$E$5000,$A25,거래내역!$B$2:$B$5000,설정!$B$3,거래내역!$H$2:$H$5000,설정!$B$5))) | G25: =IF(OR(A25="",N(E25)=0),"",F25/E25) | H25: =IF(A25="","",E25-F25) | I25: =IF(OR(A25="",N(E25)=0),"",IF(G25>1,"🔴 초과",IF(AND(G25>=0.9,B25<>"고정비"),"⚠ 주의","✅ 양호"))) | J25: =IF($A25="","",IF($C25="연",SUMIFS(거래내역!$D$2:$D$5000,거래내역!$E$2:$E$5000,$A25,거래내역!$L$2:$L$5000,">="&설정!$B$8,거래내역!$L$2:$L$5000,"<="&설정!$B$7,거래내역!$H$2:$H$5000,"본인"),SUMIFS(거래내역!$D$2:$D$5000,거래내역!$E$2:$E$5000,$A25,거래내역!$B$2:$B$5000,설정!$B$3,거래내역!$H$2:$H$5000,"본인"))) | K25: =IF($A25="","",IF($C25="연",SUMIFS(거래내역!$D$2:$D$5000,거래내역!$E$2:$E$5000,$A25,거래내역!$L$2:$L$5000,">="&설정!$B$8,거래내역!$L$2:$L$5000,"<="&설정!$B$7,거래내역!$H$2:$H$5000,"배우자"),SUMIFS(거래내역!$D$2:$D$5000,거래내역!$E$2:$E$5000,$A25,거래내역!$B$2:$B$5000,설정!$B$3,거래내역!$H$2:$H$5000,"배우자"))) | L25: =IF($A25="","",IF($C25="연",SUMIFS(거래내역!$D$2:$D$5000,거래내역!$E$2:$E$5000,$A25,거래내역!$L$2:$L$5000,">="&설정!$B$8,거래내역!$L$2:$L$5000,"<="&설정!$B$7,거래내역!$H$2:$H$5000,"공동"),SUMIFS(거래내역!$D$2:$D$5000,거래내역!$E$2:$E$5000,$A25,거래내역!$B$2:$B$5000,설정!$B$3,거래내역!$H$2:$H$5000,"공동"))) | M25: =IF(ISNUMBER(SEARCH("초과",I25)),A25&" "&TEXT(G25,"0%"),"")
B26: =IF(A26="","",IFERROR(INDEX(카테고리!$B$2:$B$200,MATCH(A26,카테고리!$A$2:$A$200,0)),"?")) | E26: =IF(A26="","",IF(C26="연",D26*설정!$B$9/12,D26)) | F26: =IF($A26="","",IF($C26="연",SUMIFS(거래내역!$D$2:$D$5000,거래내역!$E$2:$E$5000,$A26,거래내역!$L$2:$L$5000,">="&설정!$B$8,거래내역!$L$2:$L$5000,"<="&설정!$B$7,거래내역!$H$2:$H$5000,설정!$B$5),SUMIFS(거래내역!$D$2:$D$5000,거래내역!$E$2:$E$5000,$A26,거래내역!$B$2:$B$5000,설정!$B$3,거래내역!$H$2:$H$5000,설정!$B$5))) | G26: =IF(OR(A26="",N(E26)=0),"",F26/E26) | H26: =IF(A26="","",E26-F26) | I26: =IF(OR(A26="",N(E26)=0),"",IF(G26>1,"🔴 초과",IF(AND(G26>=0.9,B26<>"고정비"),"⚠ 주의","✅ 양호"))) | J26: =IF($A26="","",IF($C26="연",SUMIFS(거래내역!$D$2:$D$5000,거래내역!$E$2:$E$5000,$A26,거래내역!$L$2:$L$5000,">="&설정!$B$8,거래내역!$L$2:$L$5000,"<="&설정!$B$7,거래내역!$H$2:$H$5000,"본인"),SUMIFS(거래내역!$D$2:$D$5000,거래내역!$E$2:$E$5000,$A26,거래내역!$B$2:$B$5000,설정!$B$3,거래내역!$H$2:$H$5000,"본인"))) | K26: =IF($A26="","",IF($C26="연",SUMIFS(거래내역!$D$2:$D$5000,거래내역!$E$2:$E$5000,$A26,거래내역!$L$2:$L$5000,">="&설정!$B$8,거래내역!$L$2:$L$5000,"<="&설정!$B$7,거래내역!$H$2:$H$5000,"배우자"),SUMIFS(거래내역!$D$2:$D$5000,거래내역!$E$2:$E$5000,$A26,거래내역!$B$2:$B$5000,설정!$B$3,거래내역!$H$2:$H$5000,"배우자"))) | L26: =IF($A26="","",IF($C26="연",SUMIFS(거래내역!$D$2:$D$5000,거래내역!$E$2:$E$5000,$A26,거래내역!$L$2:$L$5000,">="&설정!$B$8,거래내역!$L$2:$L$5000,"<="&설정!$B$7,거래내역!$H$2:$H$5000,"공동"),SUMIFS(거래내역!$D$2:$D$5000,거래내역!$E$2:$E$5000,$A26,거래내역!$B$2:$B$5000,설정!$B$3,거래내역!$H$2:$H$5000,"공동"))) | M26: =IF(ISNUMBER(SEARCH("초과",I26)),A26&" "&TEXT(G26,"0%"),"")
